Workbook

Sheet 英雄基础信息配置表
A1: 英雄id | B1: 名字 | C1: 资源id | D1: 幻影资源名 | E1: 是否有 武器资源 | F1: 轮胎资源 有的行走有痕迹(1履带,2轮胎) | G1: 头像 | H1: 一次连续出多少单位 | I1: 多少数量集合成一个单位 (多步兵集合在一起) | J1: 职业 | K1: 单位类型 0、机械的（飞机坦克）默认 1、建筑 2、生物（人类、狗） | L1: 兵种 0:其他 1：坦克类 2：战车类 3：飞机类 4：士兵类 | M1: 必填 单位所在范围 0、陆地 1、空中 | N1: 飞行方式 0、漂浮类 1、盘旋 | O1: 飞行高度 | P1: 在地图上的占位 (默认是占一格) 写2（表示长宽2,占4格） 写3（表示长宽3,占9格） | Q1: 路障 额外占用可行走区域 {-1,-1},{1,1} 相对于路障点周围的点 | R1: 所占的人口 | S1: 生产时间(毫秒) | T1: 主武器伤害对装甲 2500,2500,2500,7500,10000,10000,6500,6500,6000,2500,10000 10000为分母 | U1: 副武器伤害对装甲 加成 | V1: 必填 攻击空中 陆地 0、陆地 1、空中 2、全部 | W1: 装甲类型 1无盔甲、2英雄盔甲、3重型盔甲、4轻型装甲、5中型装甲、6重型装甲、7建筑:木质材料、8建筑:钢铁材料、9建筑:钢筋混凝土材料、10轻型特殊装甲、11重型特殊装甲 | X1: 目标优先级(填职业) | Y1: 忽略列表（填职业） | Z1: 炮弹值(飞机有效) 武器类型,炮弹值 1,3 表示主武器炮弹值3 2,4 表示副武器炮弹值4 副武器炮弹值消耗完了不会回家装弹 | AA1: 主攻击间隔(ms) | AB1: 副武器攻击间隔 | AC1: 移动速度(走一格多少毫秒) 为-1时,不能移动,对时空军团兵来说该值为传送后每一格距离僵直时间 | AD1: 转身速度 (多少毫秒转一圈) 飞机移动速度越快 转圈速度也要越快 | AE1: 主武器 攻击范围 【最大攻击距离，最小攻击距离（可不填）】 10,4 (表示最大攻击10，最小攻4) 9 （表示最大攻击9，最小可不填） | AF1: 副武器 攻击范围 【最大攻击距离，最小攻击距离（可不填）】 10,4 (表示最大攻击10，最小攻4) 9 （表示最大攻击9，最小可不填） | AG1: eye范围 10,4 (表示视野10，最小视野4) 注：最小视野范围可不填 | AH1: 技能01 | AI1: 技能发招顺序 | AJ1: 副武器 技能02 | AK1: 技能发招顺序 | AL1: 可载多少人 | AM1: 可载什么职业 | AN1: 不同职业，炮台改变资源 没变的不填 不同炮台这样填 "x","xxx","xx" | AO1: 不同职业乘客 改变运兵车技能 | AP1: 伤害对装甲 1无盔甲、2英雄盔甲、3重型盔甲、4轻型装甲、5中型装甲、6重型装甲、7建筑:木质材料、8建筑:钢铁材料、9建筑:钢筋混凝土材料、10轻型特殊装甲、11重型特殊装甲 加成变化 (第x类装甲,百分比,第y类装甲,百分比,....)（10000为基数） {1,500,4,-200},{1,500,4,-200} | AQ1: 载人后增加属性种类 1：当前hp, 2：最大hp(生命上限) 3：移动速度 4：主武器攻击 5：副武器攻击 6：主武器攻击速度 7：副武器攻击速度 8:防御 | AR1: 载人后增加对应的属性百份比 （10000为基数） | AS1: 载人后对应职业切换的ai | AT1: s音效 可以有多个 "hero1001" 或者 "hero1001","hero1002" | AU1: 一直加在英雄身上的特效 | AV1: 移动特效 | AW1: 待机特效 | AX1: 死亡特效 | AY1: 尸体特效 死亡后留在场景 | AZ1: 死亡技能 | BA1: 特殊AI 0.普通AI 1、轰炸机AI 2.幻影坦克AI 3.超时空军团兵AI 4.多功能运兵车 5.心灵控制AI 6.谭雅AI 7.恐怖机械人AI 8.冷冻直升机AI 9.法国巨炮AI 10.神经突击车AI 11.工程师AI 12.间谍AI 13.娜塔莎AI 14.自爆AI 15.空母AI 16.空母战机 17.士兵ai 不动的时候防御提高 18.警犬ai 19.飞碟AI,停留时使附机械单位瘫痪 20.天启AI,场上天启越多就越硬,加BUFF 21.灰熊AI,场上有大兵提升灰熊攻速,能发现幻影 22 鬼王机甲 死亡爆炸 尸体停留 | BB1: 免疫xx,免疫是 默认是可以 第1位=1,表示免疫心灵控制,不会给控制 第2位=1,表示免疫爆破,不会给谭雅绑炸弹 第3位=1,表示免疫寄生,不会给恐怖机械人寄生 第4位=1,表示免疫冰冻,不会给冷冻直升机冰冻 第5位=1,表示免疫混乱,不会让神经突击车变混乱 第6位=1,表示不能修理,不能让工程师修理 第7位=1,可以识别间谍 | BC1: 心灵控制数量 | BD1: 单位出场动画 总部有 法国巨炮有 | BE1: 属性系数 | BF1: 英雄简介 () | BG1: 是否可为机器人 0：不可配置为机器人 1：可以 | BH1: 定位 | BI1: 主武器名字 | BJ1: 副武器名字 | BK1: 装甲名字 | BL1: 图鉴 | BM1: 载人后副武器技能 | BN1: 出现 | BO1: 能力（1-5） | BR1: 副武器
A2: id | B2: name | C2: res | D2: illusory | E2: atkRes | F2: tyre | G2: head | H2: heroNum | I2: avNum | J2: career | K2: heroType | L2: arm | M2: scope | N2: flyType | O2: flyHeight | P2: posLength | Q2: occupy | R2: populace | S2: pTime | T2: atkRate | U2: atkRate_1 | V2: atkScope | W2: defType | X2: priority | Y2: ignore | Z2: bombNum | AA2: main_atkCD | AB2: minor_atkCD | AC2: speed | AD2: turnSpeed | AE2: atkRange | AF2: atkRange_1 | AG2: warnRange | AH2: skills | AI2: skillTurn | AJ2: skills_1 | AK2: skillTurn_1 | AL2: passengerNum | AM2: passengerCareer | AN2: passengerAtkRes | AO2: passengerSkill | AP2: passengerAtkRate | AQ2: passengerAttType | AR2: passengerAttRate | AS2: passengerAI | AT2: effect | AU2: heroMagic | AV2: moveMagic | AW2: standMagic | AX2: dieMagic | AY2: corpseMagic | AZ2: dieSkill | BA2: speciaAI | BB2: immune | BC2: charmNum | BD2: comeOutRes | BE2: attrFactor | BF2: desc | BG2: robot | BH2: designing | BI2: main_atk_name | BJ2: minor_atk_name | BK2: defName | BL2: card | BM2: passengerSkill_1
A3: int | B3: string | C3: string | D3: string | E3: int | F3: int | G3: int | H3: int | I3: int | J3: int | K3: int | L3: int | M3: int | N3: int | O3: int | P3: int | Q3: array | R3: int | S3: int | T3: array | U3: array | V3: array | W3: int | X3: array | Y3: array | Z3: array | AA3: int | AB3: int | AC3: int | AD3: int | AE3: array | AF3: array | AG3: array | AH3: array | AI3: array | AJ3: array | AK3: array | AL3: int | AM3: array | AN3: array | AO3: array | AP3: array | AQ3: array | AR3: array | AS3: array | AT3: array | AU3: array | AV3: array | AW3: array | AX3: array | AY3: int | AZ3: array | BA3: int | BB3: array | BC3: int | BD3: string | BE3: float | BF3: string | BG3: int | BH3: string | BI3: string | BJ3: string | BK3: string | BL3: int | BM3: array
A4: 1001 | B4: 幻影坦克 | C4: hero/MirageTank | D4: fight_tree | E4: 1 | F4: 1 | G4: 101001 | J4: 121 | K4: 0 | L4: 1 | M4: 0 | P4: 1 | R4: 2 | S4: 99999999 | T4: 15000,15000,14000,5000,5000,5000,3000,2000,2000,10000,10000 | V4: 0 | W4: 4 | X4: 1,2,110 | Y4: 5,6,7 | AA4: 4200 | AC4: 555 | AE4: 5 | AG4: 10 | AH4: 10810 | AI4: 1 | AT4: "s_standingBy" | AV4: 100 | AX4: 107 | BA4: 2 | BB4: 0,0,0,0,0,0,0 | BE4: 1 | BF4: 可以伪装成树木来隐藏自己，随后突然发动袭击。 | BG4: 0 | BH4: 进攻型单位 | BI4: 光谱散射炮 | BJ4: 无 | BK4: 乔巴姆装甲 | BL4: 111001 | BN4: 第一次测试 | BO4: 4 | BQ4: 宝箱
A5: 1002 | B5: 天启坦克 | C5: hero/ApocalypseTank | E5: 1 | F5: 1 | G5: 101002 | J5: 122 | K5: 0 | L5: 1 | M5: 0 | P5: 1 | R5: 4 | S5: 99999999 | T5: 2500,2500,2500,7500,10000,10000,10000,10000,7000,6000,10000 | U5: 10000,9000,8000,7000,3500,3500,7500,4000,2000,8000,10000 | V5: 0,1 | W5: 6 | X5: 1,2,110 | AA5: 3180 | AB5: 5000 | AC5: 800 | AE5: 4 | AF5: 3 | AG5: 12 | AH5: 10010 | AI5: 1 | AJ5: 10011 | AK5: 1 | AT5: "s_MovingOut" | AU5: 103 | AV5: 100,13 | AX5: 107 | BA5: 20 | BB5: 0,0,0,0,0,0,0 | BE5: 1 | BF5: 最坚实可靠的坦克,场上的天启越多,单体防御就越高,防空能力有限。 | BG5: 0 | BH5: 进攻型单位 | BI5: 龙式加农炮 | BJ5: 猛犸牙防空导弹 | BK5: 自愈型装甲 | BL5: 111002 | BN5: 第一次测试 | BO5: 5 | BQ5: 宝箱 | BR5: 有
A6: 1003 | B6: 犀牛坦克 | C6: hero/Rhino | E6: 1 | F6: 1 | G6: 101003 | J6: 101 | K6: 0 | L6: 1 | M6: 0 | P6: 1 | R6: 2 | S6: 99999999 | T6: 2500,2500,1500,7500,10000,10000,6500,4500,6000,6000,10000 | V6: 0 | W6: 6 | X6: 1,2,110 | AA6: 3900 | AC6: 600 | AE6: 4 | AG6: 8 | AH6: 11810 | AI6: 1 | AT6: "s_RhinoBorn" | AV6: 101 | AX6: 107 | BA6: 0 | BB6: 0,0,0,0,0,0,0 | BE6: 1 | BF6: 便宜，高效，但炮击对防御工事内的士兵伤害不高。 | BG6: 1 | BH6: 进攻型单位，支援型单位 | BI6: 自供弹滑膛炮 | BJ6: 无 | BK6: 复合装甲 | BL6: 111003 | BN6: 第一次测试 | BO6: 2 | BP6: 送
A7: 1004 | B7: 坦克杀手 | C7: hero/tankKiller | E7: 1 | F7: 1 | G7: 101004 | J7: 101 | K7: 0 | L7: 1 | M7: 0 | P7: 1 | R7: 3 | S7: 99999999 | T7: 200,200,200,30000,12000,30000,200,200,200,200,10000 | V7: 0 | W7: 6 | X7: 101,107,108,111,112,113,114,115,121,122,123,124 | AA7: 4200 | AC7: 700 | AE7: 4 | AG7: 10 | AH7: 11410 | AI7: 1 | AT7: "s_tankKillerBorn" | AV7: 100 | AX7: 107 | BA7: 0 | BB7: 0,0,0,0,0,0,0 | BE7: 1 | BF7: 所有重甲类单位的恶梦，但那飞机好像一点都不怕他。 | BG7: 0 | BH7: 辅助型单位 | BI7: 贫铀穿甲炮 | BJ7: 无 | BK7: 复合装甲 | BL7: 111004 | BN7: 第一次测试 | BO7: 3
A8: 1005 | B8: 灰熊坦克 | C8: hero/GrizzlyTank | E8: 1 | F8: 1 | G8: 101005 | J8: 101 | K8: 0 | L8: 1 | M8: 0 | P8: 1 | R8: 2 | S8: 99999999 | T8: 7000,7000,5000,7500,10000,10000,6500,4500,6000,6000,10000 | V8: 0 | W8: 6 | X8: 1,2,110 | AA8: 3600 | AC8: 666 | AE8: 4 | AG8: 10 | AH8: 11610 | AI8: 1 | AT8: "s_GrizzlyTankBorn" | AV8: 101 | AX8: 107 | BA8: 21 | BB8: 0,0,0,0,0,0,0 | BE8: 1 | BF8: 便宜，高效，利用量大的优势形成钢铁洪流冲垮敌人。 | BG8: 1 | BH8: 支援型单位，进攻型单位 | BI8: 线膛炮 | BJ8: 无 | BK8: 复合装甲 | BL8: 111005 | BN8: 第一次测试 | BO8: 2 | BP8: 送
A9: 1006 | B9: 光棱 | C9: hero/MirageTank | E9: 1 | F9: 1 | G9: 101006 | J9: 101 | K9: 0 | L9: 1 | M9: 0 | P9: 1 | R9: 2 | S9: 99999999 | T9: 10000,10000,8000,10000,10000,10000,3000,2000,2000,10000,10000 | V9: 0 | W9: 4 | X9: 1,2,110 | Y9: 5,6,7 | AA9: 4200 | AC9: 666 | AE9: 5 | AG9: 10 | AH9: 10810 | AI9: 1 | AT9: "s_standingBy" | AV9: 100 | AX9: 107 | BA9: 2 | BB9: 0,0,0,0,0,0,0 | BE9: 1 | BF9: 当死神把光线当做镰刀，激光溅射使成片的敌人将倒下他的身下。 | BG9: 0 | BH9: 进攻型单位，辅助型单位 | BI9: 光棱透镜炮台 | BJ9: 无 | BK9: 轻便装甲 | BL9: 111006 | BO9: 4
A10: 1007 | B10: 磁能坦克 | C10: hero/teslaTank | E10: 1 | F10: 1 | G10: 101007 | J10: 101 | K10: 0 | L10: 1 | M10: 0 | P10: 1 | R10: 2 | S10: 99999999 | T10: 30000,30000,30000,8500,10000,10000,5000,5000,5000,20000,10000 | V10: 0 | W10: 6 | X10: 103,116,110,119,117,118 | Y10: 5,6,7 | AA10: 4500 | AC10: 666 | AE10: 3 | AG10: 10 | AH10: 11010 | AI10: 1 | AT10: "s_Electrodesready" | AU10: 104 | AV10: 100 | AX10: 107 | BA10: 0 | BB10: 0,0,0,0,0,0,0 | BE10: 1 | BF10: 运用特拉斯能量形成致命的电流。对士兵杀伤力巨大。 | BG10: 1 | BH10: 支援型单位 | BI10: 磁爆线圈 | BJ10: 无 | BK10: 钢腔绝缘装甲 | BL10: 111007 | BN10: 第一次测试 | BO10: 3.5
A11: 1008 | B11: 遥控坦克 | C11: hero/RobotTank | E11: 1 | G11: 101008 | J11: 112 | K11: 0 | L11: 1 | M11: 0 | P11: 1 | R11: 2 | S11: 99999999 | T11: 2500,2500,1500,7500,10000,10000,6500,4500,6000,6000,10000 | V11: 0 | W11: 6 | X11: 110,107 | AA11: 3600 | AC11: 666 | AE11: 4 | AG11: 12 | AH11: 12310 | AI11: 1 | AT11: "s_RobotTankBORN" | AV11: 101 | AX11: 133 | BA11: 0 | BB11: 1,0,0,0,1,0,0 | BE11: 1 | BF11: 遥控坦克并没有驾驶人员，所以不受心灵控制/神经毒气的影响。 | BG11: 1 | BH11: 支援型单位，进攻型单位 | BI11: 近距85mm双管炮 | BJ11: 无 | BK11: 铝合金装甲 | BL11: 111008 | BN11: 第一次测试 | BO11: 3
A12: 1009 | B12: 盖特坦克 | C12: hero/gateTank | E12: 1 | F12: 1 | G12: 101009 | J12: 101 | K12: 0 | L12: 1 | M12: 0 | P12: 1 | R12: 2 | S12: 99999999 | T12: 20000,16000,14000,3000,2000,800,1000,500,300,20000,5000 | V12: 2 | W12: 4 | X12: 103,116,110,119,117,118 | AA12: 1200 | AC12: 666 | AE12: 3 | AG12: 10 | AH12: 10610 | AI12: 1 | AT12: "s_easyTarget" | AV12: 100 | AX12: 107 | BA12: 0 | BB12: 0,0,0,0,0,0,0 | BE12: 1 | BF12: 这种坦克装备着两口大型机关枪，可以对空或对地。对士兵/轻甲单位杀伤力巨大。 | BG12: 1 | BH12: 支援型单位，进攻型单位 | BI12: 液氮加特林机枪 | BJ12: 无 | BK12: 铝合金装甲 | BL12: 111009 | BN12: 第一次测试 | BO12: 1.5 | BP12: 送
A13: 1010 | B13: 未来坦克 | C13: hero/FutureTank | F13: 1 | G13: 101010 | J13: 123 | K13: 0 | L13: 1 | M13: 0 | P13: 2 | R13: 4 | S13: 99999999 | T13: 2500,2500,2500,7500,10000,10000,10000,10000,7000,6000,10000 | V13: 0,1 | W13: 6 | X13: 1,2,110 | AA13: 3000 | AC13: 800 | AE13: 4 | AG13: 10 | AH13: 12710 | AI13: 1 | AT13: "s_SUHamme_VoiAttacke" | AU13: 137 | AX13: 107 | BA13: 0 | BB13: 1,0,1,1,1,0,0 | BE13: 1 | BF13: 高级电脑控制的坦克。不受心灵控制/神经毒气/时空旋涡/寄生的影响。 | BG13: 0 | BH13: 进攻型单位 | BI13: 中子扰动炮 | BJ13: 无 | BK13: 未来装甲 | BL13: 111010 | BO13: 5.5
A14: 1011 | B14: 鬼王机甲 | C14: hero/KingOni | G14: 101011 | J14: 124 | K14: 0 | L14: 1 | M14: 0 | P14: 2 | R14: 5 | S14: 99999999 | T14: 10000,10000,8000,10000,10000,10000,3000,2000,2000,10000,10000 | U14: 10000,8000,6000,16000,15000,15000,10000,10000,6000,10000,10000 | V14: 0,2 | W14: 6 | X14: 1,2,110 | AA14: 2000 | AB14: 5000 | AC14: 600 | AE14: 4 | AF14: 5 | AG14: 10 | AH14: 12810 | AI14: 1 | AJ14: 12812 | AK14: 1 | AT14: "s_JUKingO_VoiMovAttd" | AV14: 135 | AZ14: 12811 | BA14: 22 | BB14: 1,0,1,1,1,0,0 | BE14: 1 | BF14: 横行陆地。不受心灵控制/神经毒气/冷冻/寄生的影响。 | BG14: 0 | BH14: 进攻型单位 | BI14: 双眼死光炮 | BJ14: 无 | BK14: 复合装甲 | BL14: 111011 | BN14: 第一次测试 | BO14: 6
A15: 2001 | B15: 多功能车 | C15: hero/MultInfantryVeh | E15: 1 | F15: 2 | G15: 102001 | J15: 115 | K15: 0 | L15: 2 | M15: 0 | P15: 1 | R15: 3 | S15: 99999999 | T15: 10000,10000,10000,7000,7000,3500,7500,4000,2000,8000,10000 | V15: 0 | W15: 4 | X15: 1,2,110 | AA15: 1000 | AC15: 800 | AE15: 4 | AG15: 12 | AH15: 13110 | AI15: 1 | AL15: 1 | AM15: 103,116,109 | AN15: "x","xxxxx","xx" | AO15: 13110,13111,13112 | AP15: {1,2000,2,2000,3,2000,4,2000,5,2000},{1,3333,2,3333,3,3333},{1,2000,2,2000,3,2000,4,2000,5,2000} | AQ15: {2,4,8},{2,4,8},{2,4,8} | AR15: {10000,10000,10000},{10000,10000,10000},{10000,10000,10000} | AS15: 0,3,0 | AT15: "s_AUIFV_VoiCreatea" | AV15: 100 | AX15: 107 | BA15: 4 | BB15: 0,0,0,0,0,0,0 | BE15: 1 | BF15: 会因内部搭载的士兵部队而改变其武装,士兵越强,战车越强。 | BG15: 1 | BH15: 进攻型单位 | BI15: 特殊多功能炮塔 | BJ15: 无 | BK15: 复合装甲 | BL15: 112001 | BM15: 12511 | BN15: 第一次测试 | BO15: 4 | BR15: 有
A16: 2002 | B16: 恐怖机器人 | C16: hero/TerrorDrone | F16: 1 | G16: 102002 | J16: 108 | K16: 0 | L16: 2 | M16: 0 | P16: 1 | R16: 2 | S16: 99999999 | T16: 10000,8000,8000,5000,2500,2500,7500,5000,2500,10000,10000 | U16: 10000,8000,8000,15000,25000,25000,7500,5000,2500,10000,10000 | V16: 0,0 | W16: 4 | X16: 1,2,110 | Y16: 3,4,5,6,7 | AA16: 3600 | AB16: 2000 | AC16: 666 | AE16: 1 | AG16: 8 | AH16: 11910 | AI16: 1 | AJ16: 11911 | AK16: 1 | AT16: "s_TerrorDronea" | AX16: 107 | BA16: 7 | BB16: 1,0,1,0,1,0,0 | BE16: 1 | BF16: 被恐怖机器人所寄生是大部分机械单位的克星，速度快，攻击力强。 | BG16: 0 | BH16: 辅助型单位 | BI16: 铱合金拆卸爪 | BJ16: 无 | BK16: 铝合金装甲 | BL16: 112002 | BO16: 3 | BP16: 送
A17: 2003 | B17: 自爆卡车 | C17: hero/ExplosiveTruck | F17: 2 | G17: 102003 | J17: 111 | K17: 0 | L17: 2 | M17: 0 | P17: 1 | R17: 2 | S17: 99999999 | T17: 50000,50000,50000,50000,50000,50000,40000,75000,50000,50000,50000 | V17: 0 | W17: 4 | X17: 1,2,110 | AA17: 1000 | AC17: 800 | AE17: 1 | AG17: 10 | AH17: 12210 | AI17: 1 | AT17: "s_ExplosiveTruckBorn" | AV17: 100 | AZ17: 12210 | BA17: 14 | BB17: 0,0,1,0,0,0,0 | BE17: 1 | BF17: 向敌人发动自杀式爆炸，并产生核辐射对敌人造成持续伤害。 | BG17: 0 | BH17: 辅助型单位 | BI17: 小型自爆核弹 | BJ17: 无 | BK17: 铝合金装甲 | BL17: 112003 | BO17: 3
A18: 2004 | B18: 心灵控制车 | C18: hero/MasterMind | F18: 1 | G18: 102004 | J18: 110 | K18: 0 | L18: 2 | M18: 0 | P18: 1 | R18: 4 | S18: 99999999 | T18: 10000,10000,10000,5000,5000,5000,0,0,0,0,0 | U18: 10000,10000,10000,5000,5000,5000,0,0,0,0,0 | V18: 0,0 | W18: 6 | X18: 1,2 | AA18: 5000 | AB18: 5000 | AC18: 1000 | AE18: 4 | AF18: 1 | AG18: 14 | AH18: 12110 | AI18: 1 | AJ18: 12111 | AK18: 1 | AT18: "s_makeItGrow" | AV18: 100 | AX18: 107 | BA18: 5 | BB18: 1,0,0,0,1,0,1 | BC18: 1 | BE18: 1 | BF18: 能控制敌方地面部队的战车，据说能求出敌人的心理阴影面积。 | BG18: 0 | BH18: 辅助型单位 | BI18: 主脑控制仪 | BJ18: 中型心灵冲击装置 | BK18: 自我修复装甲 | BL18: 112004 | BN18: 第一次测试 | BO18: 4 | BQ18: 宝箱
A19: 2005 | B19: 防空车 | C19: hero/AirDefenseTrackedVehicle | E19: 1 | F19: 1 | G19: 102005 | J19: 105 | K19: 0 | L19: 2 | M19: 0 | P19: 1 | R19: 2 | S19: 99999999 | T19: 20000,17500,15000,23000,15000,10000,8000,7000,6000,10000,10000 | V19: 1 | W19: 6 | X19: 105 | AA19: 1500 | AC19: 666 | AE19: 5 | AG19: 19 | AH19: 11210 | AI19: 1 | AT19: "s_yesCommander" | AV19: 100 | AX19: 107 | BA19: 0 | BB19: 0,0,0,0,0,0,0 | BE19: 1 | BF19: 这款轻型装甲车看起来打不过任何坦克，但这是所有飞行单位的恶梦。 | BG19: 1 | BH19: 辅助型单位 | BI19: 高射破片防空炮 | BJ19: 无 | BK19: 轻型装甲 | BL19: 112005 | BN19: 第一次测试 | BO19: 2.5
A20: 2006 | B20: V3火箭 | C20: hero/V3rocket | F20: 1 | G20: 102006 | J20: 101 | K20: 0 | L20: 2 | M20: 0 | P20: 1 | R20: 3 | S20: 99999999 | T20: 10000,10000,10000,22500,15000,15000,60000,60000,60000,30000,30000 | V20: 0 | W20: 4 | X20: 0 | AA20: 9400 | AC20: 2000 | AE20: 6 | AG20: 11,3 | AH20: 10710 | AI20: 1 | AT20: "s_v3build" | AV20: 101 | AX20: 107 | BA20: 0 | BB20: 0,0,0,0,0,0,0 | BE20: 1 | BF20: 当你还没看到他时，你已经在他的射程范围之内了。 | BG20: 0 | BH20: 进攻型单位 | BI20: V3飞弹 | BJ20: 无 | BK20: V3装甲 | BL20: 112006 | BN20: 第一次测试 | BO20: 3.5
A21: 2007 | B21: 神经突击车 | C21: hero/ChaosCar | F21: 2 | G21: 102007 | J21: 107 | K21: 0 | L21: 2 | M21: 0 | P21: 1 | R21: 2 | S21: 99999999 | T21: 10000,10000,10000,5000,5000,5000,0,0,0,0,0 | V21: 0 | W21: 4 | X21: 1,2,110 | Y21: 5,6,7 | AA21: 1800 | AC21: 666 | AE21: 1 | AG21: 10 | AH21: 11710 | AI21: 1 | AT21: "s_ChaosCar" | AV21: 100,13 | AX21: 107 | BA21: 10 | BB21: 0,0,0,0,0,0,0 | BE21: 1 | BF21: 当其散发出神经毒气云时，就要注意你的同伴，他们会狂暴的向你开火。 | BG21: 0 | BH21: 辅助型单位 | BI21: 毒气轮盘喷管 | BJ21: 无 | BK21: 铝合金装甲 | BL21: 112007 | BO21: 2
A22: 2008 | B22: 战斗要塞 | C22: hero/BattleFortress | F22: 1 | G22: 102008 | J22: 101 | K22: 0 | L22: 2 | M22: 0 | P22: 2 | R22: 4 | S22: 99999999 | T22: 10000,8000,7000,5000,2000,2000,2000,1500,1000,40000,10000 | U22: 2000,2000,2000,10000,5000,10000,1000,1000,1000,10000,10000 | V22: 0,1 | W22: 6 | X22: 1,2,110 | AA22: 1200 | AB22: 6000 | AC22: 1000 | AE22: 4 | AF22: 4 | AG22: 12 | AH22: 12510 | AI22: 1 | AL22: 3 | AM22: 103 | AO22: 12510 | AP22: {1,2000,2,2000,3,2000,4,2000,5,2000},{1,3333,2,3333,3,3333},{1,2000,2,2000,3,2000,4,2000,5,2000} | AQ22: {2,4,8} | AR22: {10000,10000,10000} | AS22: 0 | AT22: "s_BattleFortressBorn" | AV22: 100 | AX22: 107 | BA22: 0 | BB22: 0,0,0,0,0,0,0 | BE22: 1 | BF22: 这个大型的战车搭载士兵后能发射对空/对地导弹,同时属性大增。 | BG22: 0 | BH22: 进攻型单位 | BI22: 多管自动炮塔 | BJ22: 标枪导弹 | BK22: 要塞装甲 | BL22: 112008 | BM22: 12511 | BO22: 4 | BR22: 有
A23: 2009 | B23: 武装采矿车 | C23: hero/warMiner | E23: 1 | F23: 1 | G23: 102009 | J23: 114 | K23: 0 | L23: 2 | M23: 0 | P23: 1 | R23: 2 | S23: 99999999 | T23: 10000,8000,7000,5000,2000,2000,2000,1500,1000,40000,10000 | U23: 5000,5000,5000,10000,10000,10000,10000,10000,10000,10000,10000 | V23: 0,0 | W23: 5 | X23: 1,2,110 | AA23: 1200 | AB23: 6000 | AC23: 1000 | AE23: 4 | AF23: 4 | AG23: 8 | AH23: 13010 | AI23: 1 | AT23: "s_AUProsp_VoiCreateb" | AV23: 100 | AX23: 107 | BA23: 0 | BB23: 1,0,0,0,1,0,0 | BE23: 1 | BF23: 平时只采矿，进入战斗时架设机枪，杀伤敌人。无视心灵控制/神经毒气 | BG23: 0 | BH23: 进攻型单位 | BI23: 小型自动炮塔 | BJ23: 采矿炸药 | BK23: 复合装甲 | BL23: 112009 | BO23: 2.5 | BR23: 有
A24: 2010 | B24: 法国巨炮 | C24: hero/GrandCannon | E24: 1 | F24: 1 | G24: 102010 | J24: 113 | K24: 0 | L24: 2 | M24: 0 | P24: 1 | R24: 3 | S24: 99999999 | T24: 10000,10000,10000,7500,7500,7500,10000,10000,5000,10000,10000 | V24: 0,1 | W24: 7 | X24: 110 | Y24: 1,2 | AA24: 7200 | AC24: -1 | AE24: 14 | AG24: 15,3 | AH24: 12610 | AI24: 1 | AT24: "s_OpenFire" | AV24: 100 | AX24: 129 | BA24: 9 | BB24: 0,0,0,0,0,0,0 | BE24: 1 | BF24: 超强的攻击力，超远的射程，能有效防卫基地，抵御敌方地面的攻击。 | BG24: 0 | BH24: 防御型单位 | BI24: 200mm撞击榴弹炮 | BJ24: 无 | BK24: 重型装甲 | BL24: 112010 | BN24: 第一次测试 | BO24: 2.5 | BR24: 有
A25: 2011 | B25: 将军刽子手 | C25: hero/KingOni | G25: 101011 | J25: 124 | K25: 0 | L25: 1 | M25: 0 | P25: 2 | R25: 7 | S25: 99999999 | T25: 10000,10000,8000,10000,10000,10000,3000,2000,2000,10000,10000 | V25: 0,1 | W25: 6 | X25: 1,2,110 | AA25: 2000 | AC25: 600 | AE25: 4 | AG25: 10 | AH25: 12810 | AI25: 1 | AT25: "s_JUKingO_VoiMovAttd" | AV25: 135 | AX25: 107 | BA25: 0 | BB25: 1,0,1,1,1,0,0 | BE25: 1 | BF25: 横行陆地。不受心灵控制/神经毒气/冷冻/寄生的影响。 | BG25: 0 | BH25: 进攻型单位 | BI25: 双眼死光炮 | BJ25: 无 | BK25: 复合装甲 | BL25: 111011 | BN25: 第一次测试 | BO25: 6
A26: 3001 | B26: 镭射幽浮 | C26: hero/FloatingDisk | G26: 103001 | J26: 102 | K26: 0 | L26: 3 | M26: 1 | N26: 0 | O26: 130 | P26: 1 | R26: 2 | S26: 99999999 | T26: 10000,10000,10000,5000,5000,5000,10000,10000,10000,10000,10000 | V26: 0,0 | W26: 4 | X26: 1,2,110,102,109 | Y26: 3,4,5,6,7,1,2 | AA26: 4800 | AC26: 500 | AE26: 1 | AF26: 1 | AG26: 14 | AH26: 12410 | AI26: 1 | AT26: "s_floatDiskMove" | AW26: 136 | AX26: 157 | BA26: 19 | BB26: 1,1,1,1,1,1,0 | BE26: 1 | BF26: 能有效对付地面单位，悬停时使附近机械单位受到EMP冲击而瘫痪。 | BG26: 0 | BH26: 进攻型单位 | BI26: 高斯激光炮 | BJ26: 电力吸取装置 | BK26: 记忆装甲 | BL26: 113001 | BO26: 3
A27: 3002 | B27: 基洛夫空艇 | C27: hero/KirovAirship | G27: 103002 | J27: 102 | K27: 0 | L27: 3 | M27: 1 | N27: 0 | O27: 230 | P27: 1 | R27: 4 | S27: 99999999 | T27: 10000,10000,10000,14000,13500,13500,15000,15000,5000,10000,10000 | V27: 0 | W27: 5 | X27: 1,2,2005 | Y27: 3,4,5,6,7,1,2 | AA27: 3000 | AC27: 800 | AE27: 0 | AG27: 10 | AH27: 10110 | AI27: 1 | AT27: "s_Kirovreporting" | AZ27: 10111,10112 | BA27: 0 | BB27: 1,1,1,1,1,1,0 | BE27: 1 | BF27: 专门为轰炸地面而设计的空中死神，基洛夫飞艇代表着体型、力量、坚定和信仰。 | BG27: 0 | BH27: 进攻型单位，防御型单位 | BI27: 迅雷炸弹 | BJ27: 无 | BK27: 封闭防火装甲 | BL27: 113002 | BN27: 第一次测试 | BO27: 5 | BQ27: 宝箱
A28: 3003 | B28: 武装直升机 | C28: hero/helicopter | E28: 1 | G28: 103003 | J28: 102 | K28: 0 | L28: 3 | M28: 1 | N28: 0 | O28: 130 | P28: 2 | R28: 2 | S28: 99999999 | T28: 10000,8000,8000,5000,2500,2500,7500,5000,2500,10000,10000 | U28: 10000,8000,6000,16000,15000,15000,10000,10000,6000,10000,10000 | V28: 2,0 | W28: 4 | X28: 101,107,108,111,112,113,114,115,121,122,123,124 | Y28: 3,4,5,6,7,1,2 | AA28: 900 | AB28: 6000 | AC28: 500 | AE28: 3 | AF28: 5 | AG28: 10 | AH28: 10910 | AI28: 1 | AJ28: 10911 | AK28: 1 | AT28: "s_Airtransportready" | AZ28: 10913,10912 | BA28: 0 | BB28: 1,1,1,1,1,1,0 | BE28: 1 | BF28: 强大的火力，对空能力稍弱,攻击地面是把好手 | BG28: 0 | BH28: 进攻型单位 | BI28: 复仇者机炮 | BJ28: 战斧对地导弹 | BK28: 陶瓷金属装甲 | BL28: 113003 | BN28: 第一次测试 | BO28: 2.5 | BR28: 有
A29: 3004 | B29: 入侵者战机 | C29: hero/invaderPlane | G29: 103004 | J29: 104 | K29: 0 | L29: 3 | M29: 1 | N29: 0 | O29: 170 | P29: 1 | R29: 2 | S29: 99999999 | T29: 10000,10000,20000,30000,30000,30000,30000,10000,7500,10000,10000 | U29: 10000,10000,10000,10000,10000,10000,10000,10000,7500,10000,10000 | V29: 1,0 | W29: 4 | X29: 101,107,108,111,112,113,114,115,121,122,123,124 | Y29: 3,4,5,6,7,1,2 | AA29: 600 | AB29: 2500 | AC29: 444 | AE29: 4 | AF29: 5 | AG29: 12 | AH29: 11310 | AI29: 1 | AJ29: 11311 | AK29: 1 | AT29: "s_readyToStrike" | AV29: 127 | AW29: 128 | AX29: 121,122 | BA29: 0 | BB29: 1,1,1,1,1,1,0 | BE29: 1 | BF29: 能悬停的喷气式飞机，对空远比对地强。 | BG29: 0 | BH29: 进攻型单位 | BI29: 机鼻链炮 | BJ29: 宝石路激光炸弹 | BK29: 复合装甲 | BL29: 113004 | BO29: 3
A30: 3005 | B30: 黑鹰战机 | C30: hero/blackBird | G30: 103005 | J30: 104 | K30: 0 | L30: 3 | M30: 1 | N30: 1 | O30: 200 | P30: 1 | R30: 2 | S30: 99999999 | T30: 10000,10000,10000,10000,10000,10000,10000,10000,7500,10000,10000 | V30: 0 | W30: 4 | X30: 101,107,108,111,112,113,114,115,121,122,123,124,2005 | Y30: 3,4,5,6,7,1,2 | Z30: 1,3 | AA30: 900 | AC30: 444 | AD30: 500 | AE30: 4 | AG30: 10 | AH30: 10510 | AI30: 1 | AT30: "s_BlackEaglereporting" | AU30: 102 | AZ30: 10213,10214 | BA30: 1 | BB30: 1,1,1,1,1,1,0 | BE30: 1 | BF30: “黑鹰黑鹰黑鹰”,敌人连呼三声是因为它会向地面连射三枚致命的导弹。 | BG30: 0 | BH30: 支援型单位 | BI30: AS-10对地导弹 | BJ30: 无 | BK30: 复合装甲 | BL30: 113005 | BN30: 第一次测试 | BO30: 3 | BP30: 送
A31: 3006 | B31: 冷冻直升机 | C31: hero/iceHelicopter | G31: 103006 | J31: 106 | K31: 0 | L31: 3 | M31: 1 | N31: 0 | O31: 130 | P31: 1 | R31: 2 | S31: 99999999 | T31: 10000,8000,8000,5000,2500,2500,7500,5000,2500,10000,10000 | V31: 0 | W31: 4 | X31: 1,2,110,102,109,2005 | Y31: 3,4,5,6,7,1,2 | AA31: 2400 | AC31: 500 | AE31: 5 | AG31: 10 | AH31: 11510 | AI31: 1 | AT31: "s_iceSystemReadyToGo" | AX31: 131 | BA31: 8 | BB31: 1,1,1,1,1,1,0 | BE31: 1 | BF31: 发射冷冻光束冻住地面敌人，这种能力着实是敌人的噩梦。 | BG31: 0 | BH31: 辅助型单位 | BI31: 定向冷冻光束炮 | BJ31: 无 | BK31: 复合装甲 | BL31: 113006 | BO31: 3.5
A32: 3007 | B32: 超级要塞 | C32: hero/Gigafortress | G32: 103007 | J32: 101 | K32: 0 | L32: 3 | M32: 1 | N32: 0 | O32: 100 | P32: 1 | R32: 5 | S32: 99999999 | T32: 10000,10000,10000,7500,5000,5000,20000,20000,20000,10000,10000 | U32: 2000,2000,2000,10000,5000,10000,1000,1000,1000,10000,10000 | V32: 0,1 | W32: 6 | X32: 1,2,110 | Y32: 3,4,5,6,7,1,2 | AA32: 1800 | AB32: 5000 | AC32: 666 | AE32: 2 | AF32: 4 | AG32: 10 | AH32: 12910 | AI32: 1 | AJ32: 12912 | AK32: 1 | AT32: "s_gunDamBootb" | AU32: 126 | AZ32: 12911,12911 | BA32: 0 | BB32: 1,1,1,1,1,1,0 | BE32: 1 | BF32: 悬浮空中的机械怪兽，用“神之鼻息”激光系统收割地面的敌人,能连续发射两枚空对空导弹。 | BG32: 0 | BH32: 防御型单位 | BI32: 神之鼻息装置 | BJ32: 无 | BK32: 纳米装甲 | BL32: 113007 | BO32: 5
A33: 3008 | B33: 世纪轰炸机 | C33: hero/Gigafortress | G33: 103007 | J33: 101 | K33: 0 | L33: 3 | M33: 1 | N33: 0 | O33: 100 | P33: 1 | R33: 6 | S33: 99999999 | T33: 10000,10000,10000,7500,5000,5000,20000,20000,20000,10000,10000 | V33: 0 | W33: 6 | X33: 1,2,110 | Y33: 3,4,5,6,7 | AA33: 1800 | AC33: 666 | AE33: 2 | AG33: 10 | AH33: 12910 | AI33: 1 | AT33: "s_gunDamBootb" | AU33: 126 | AZ33: 12911,12911 | BA33: 0 | BB33: 1,1,1,1,1,1,0 | BE33: 1 | BF33: 悬浮空中的机械怪兽，用“神之鼻息”激光系统收割地面的敌人。 | BG33: 0 | BH33: 防御型单位 | BI33: 神之鼻息装置 | BJ33: 无 | BK33: 纳米装甲 | BL33: 113007 | BO33: 5
A34: 3009 | B34: 双刃直升机 | C34: hero/iceHelicopter | G34: 103006 | J34: 106 | K34: 0 | L34: 3 | M34: 1 | N34: 0 | O34: 130 | P34: 1 | R34: 2 | S34: 99999999 | T34: 10000,8000,8000,5000,2500,2500,7500,5000,2500,10000,10000 | V34: 0 | W34: 4 | X34: 1,2,110,102,109 | Y34: 3,4,5,6,7 | AA34: 2400 | AC34: 500 | AE34: 5 | AG34: 10 | AH34: 11510 | AI34: 1 | AT34: "s_iceSystemReadyToGo" | AX34: 132 | BA34: 8 | BB34: 1,1,1,1,1,1,0 | BE34: 1 | BF34: 发射冷冻光束冻住地面敌人，这种能力着实是敌人的噩梦。 | BG34: 0 | BH34: 辅助型单位 | BI34: 定向冷冻光束炮 | BJ34: 无 | BK34: 复合装甲 | BL34: 113006 | BO34: 3.5
A35: 4001 | B35: 美国大兵 | C35: hero/solider | G35: 104001 | H35: 3 | J35: 103 | K35: 2 | L35: 4 | M35: 0 | P35: 1 | R35: 3 | S35: 99999999 | T35: 10000,8000,8000,5000,2500,2500,7500,5000,2500,10000,10000 | U35: 2000,2000,2000,10000,5000,10000,1000,1000,1000,10000,10000 | V35: 0,1 | W35: 3 | X35: 1,2,110 | AA35: 1200 | AB35: 7200 | AC35: 1200 | AE35: 4 | AF35: 2 | AG35: 10 | AH35: 10410 | AI35: 1 | AJ35: 10411 | AK35: 1 | AT35: "s_Siryessir" | AX35: 31,15 | BA35: 17 | BB35: 0,1,0,0,0,1,0 | BE35: 1 | BF35: 用机枪和单兵防空导弹还有血肉之躯，停下时搭建简易工事加强防御。 | BG35: 1 | BH35: 防御型单位 | BI35: M78机枪 | BJ35: 标枪单兵导弹 | BK35: 轻便型装甲 | BL35: 114001 | BN35: 第一次测试 | BO35: 2 | BP35: 送 | BR35: 有
A36: 4002 | B36: 谭雅 | C36: hero/Tanya | G36: 104002 | J36: 116 | K36: 2 | L36: 4 | M36: 0 | P36: 1 | R36: 3 | S36: 99999999 | T36: 10000,10000,10000,0,0,0,100,100,100,100,10000 | U36: 0,0,0,10000,10000,10000,10000,10000,10000,10000,10000 | V36: 0,0 | W36: 2 | X36: 110 | AA36: 900 | AB36: 6000 | AC36: 1333 | AE36: 3 | AF36: 3 | AG36: 10 | AH36: 11110 | AI36: 1 | AJ36: 11111 | AK36: 1 | AT36: "s_LetRockAndRoll" | AX36: 15 | BA36: 6 | BB36: 1,1,1,0,1,0,0 | BE36: 1 | BF36: 特战队队长，有着强悍的双枪、C4炸弹，强大的意志免疫心灵控制及神经毒气 | BG36: 1 | BH36: 进攻型单位 | BI36: 黑秃鹰特制手枪 | BJ36: C4塑胶炸弹 | BK36: 曲光型装甲 | BL36: 114002 | BN36: 第一次测试 | BO36: 3.5 | BQ36: 宝箱 | BR36: 有
A37: 4003 | B37: 娜塔莎 | C37: hero/Natasha | G37: 104003 | J37: 119 | K37: 2 | L37: 4 | M37: 0 | P37: 1 | R37: 3 | S37: 99999999 | T37: 10000,10000,10000,0,0,0,100,100,100,100,10000 | U37: 0,0,0,10000,10000,10000,10000,10000,10000,10000,10000 | V37: 0,0 | W37: 2 | X37: 1,2,110 | Y37: 3,4,5,6,7 | AA37: 1200 | AB37: 8000 | AC37: 1333 | AE37: 5 | AF37: 5 | AG37: 12 | AH37: 13310 | AI37: 1 | AJ37: 13311,13312 | AK37: 1 | AT37: "s_NatasAction" | AX37: 15 | BA37: 13 | BB37: 1,1,1,0,1,0,0 | BE37: 1 | BF37: 狙击步枪作为武器，激光引导米格战机攻击。不受心灵控制/神经毒气影响。 | BG37: 0 | BH37: 进攻型单位 | BI37: SVD狙击步枪 | BJ37: 激光指示器 | BK37: 伪装型装甲 | BL37: 114003 | BO37: 3.5 | BR37: 有
A38: 4004 | B38: 尤里X | C38: hero/yuri | G38: 104004 | J38: 110 | K38: 2 | L38: 4 | M38: 0 | P38: 1 | R38: 4 | S38: 99999999 | T38: 10000,10000,10000,5000,5000,5000,0,0,0,0,0 | U38: 10000,10000,10000,5000,5000,5000,0,0,0,0,0 | V38: 0,0 | W38: 6 | X38: 1,2 | Y38: 3,4,5,6,7 | AA38: 5000 | AB38: 5000 | AC38: 1000 | AE38: 4 | AF38: 4 | AG38: 14 | AH38: 0 | AJ38: 12111 | AK38: 1 | AT38: "s_yuriTellYourWish" | AV38: 100 | AX38: 107 | BA38: 5 | BB38: 1,0,1,0,1,0,1 | BC38: 2 | BE38: 1 | BF38: 控制(敌方地面部队)软弱的心灵，对近身敌人释放心灵爆震. | BG38: 0 | BH38: 辅助型单位 | BI38: 心灵控制仪 | BJ38: 蛇式信号放大仪 | BK38: 自我修复装甲 | BL38: 114004 | BN38: 第一次测试 | BO38: 4 | BQ38: 宝箱
A39: 4005 | B39: 时空军团兵 | C39: hero/timeTravelSolider | G39: 104005 | H39: 2 | J39: 109 | K39: 2 | L39: 4 | M39: 0 | P39: 1 | R39: 2 | S39: 99999999 | T39: 1000,1000,1000,600,400,400,750,500,250,1000,1000 | V39: 0 | W39: 3 | X39: 101,110,121,122 | Y39: 3,4,5,6,7 | AA39: 7200 | AC39: 800 | AE39: 5 | AG39: 19 | AH39: 12010 | AI39: 1 | AT39: "s_theyAreHitstory" | AV39: 125,134 | AX39: 15 | BA39: 3 | BB39: 0,1,1,0,0,1,0 | BE39: 1 | BF39: 让敌人陷入时空乱流,不能还击,不能移动,只能等待被抹杀。 | BG39: 0 | BH39: 进攻型单位 | BI39: 小型裂缝产生器 | BJ39: 无 | BK39: 时空干扰装甲 | BL39: 114005 | BN39: 第一次测试 | BO39: 3
A40: 4006 | B40: 警犬 | C40: hero/dog | G40: 104006 | H40: 2 | J40: 117 | K40: 2 | L40: 4 | M40: 0 | P40: 1 | R40: 2 | S40: 99999999 | T40: 100000,10000,10000,5000,2500,2500,7500,5000,2500,10000,10000 | U40: 10000,8000,8000,5000,2500,2500,7500,5000,2500,10000,10000 | V40: 0,0 | W40: 1 | X40: 1,2,110 | Y40: 3,4,5,6,7,105,101,107,108,111,112,113,114,115,121,122,123,124 | AA40: 1200 | AB40: 5200 | AC40: 400 | AE40: 1 | AF40: 1 | AG40: 10 | AH40: 13410 | AI40: 1 | AJ40: 13411 | AK40: 1 | AT40: "s_dogAction" | AX40: 55 | BA40: 18 | BB40: 0,1,1,0,0,1,1 | BE40: 1 | BF40: 识别间谍,Shumov-3型吼声放大器增幅怒吼震晕周围士兵类敌军3秒 | BG40: 0 | BH40: 防御型单位 | BI40: 钢腔獠牙 | BJ40: Shumov吼声放大器 | BK40: 轻便型装甲 | BL40: 114006 | BO40: 2
...

Sheet 英雄升级配置表
A1: 等级 | B1: 英雄升级需要经验 | C1: 免伤系数
A2: lev | B2: exp | C2: def_factor
A3: int | B3: int | C3: int
A4: 1 | B4: 16 | C4: 206
A5: 2 | B5: 33 | C5: 218
A6: 3 | B6: 33 | C6: 225
A7: 4 | B7: 41 | C7: 231
A8: 5 | B8: 50 | C8: 237
A9: 6 | B9: 50 | C9: 243
A10: 7 | B10: 58 | C10: 250
A11: 8 | B11: 83 | C11: 256
A12: 9 | B12: 83 | C12: 262
A13: 10 | B13: 83 | C13: 268
A14: 11 | B14: 100 | C14: 275
A15: 12 | B15: 100 | C15: 281
... A203: 200 | B203: 7782700 | C203: 39162

Sheet 英雄军衔配置表
A1: 英雄ID | B1: 品阶 | C1: 物品数量 | D1: 金币 | E1: 需要等级 | F1: 军衔附加属性 | G1: 最大库存多少 （一开始可以召唤多少只然后才有cd） | H1: 英雄名称 | I1: 能力值 | J1: 兵种 0:其他 1：坦克类 2：战车类 3：飞机类 4：士兵类 | K1: 所需勋章 | L1: 所需图纸 | M1: 所需勋章num | N1: 所需图纸num | Q1: 主攻击 | R1: 副攻击 | S1: 生命 | T1: 防御 | V1: 子项目1系数 (10000为分母) | W1: 子项目2系数 (10000为分母) | X1: 子项目3系数 (10000为分母) | Y1: 子项目4系数 (10000为分母) | AA1: 调节系数 | AB1: 标准生命 | AC1: 等级段 | AD1: 标准防御 | AE1: 免伤比 | AH1: 占人口 | AI1: 主攻击/生命 | AJ1: 副攻击/生命 | AK1: 攻击能力 主攻击/主CD | AL1: 副攻击/副cd | AM1: 主_攻击间隔 | AN1: 副_攻击间隔
A2: hero_id | B2: quality | C2: items | D2: coin | E2: level | F2: attrList | G2: stockNum
A3: int | B3: int | C3: array | D3: int | E3: int | F3: array | G3: int
A4: 1001 | B4: 1 | C4: ="{"&K4&","&ROUNDUP(M4,0)&"},"&"{"&L4&","&ROUNDUP(N4,0)&"}" -> {10111,1},{21001,2} | D4: 1000 | E4: 10 | F4: ="{1,"&INT(S4*P4)&"},{2,"&INT(Q4*P4)&"},"&IF(R4=0,"","{3,"&INT(R4*P4)&"},")&"{6,"&INT(T4*P4)&"}" -> {1,979},{2,344},{6,262} | G4: =1 -> 1 | H4: 幻影坦克 | I4: {=INDEX([1]英雄界面!$I$4:$I$41,MATCH(A4,[1]英雄界面!$A$4:$A$41,0))} -> 50 | J4: =1 -> 1 | K4: =CHOOSE(J4,INDEX([2]勋章!$I$7:$I$24,MATCH($B4,[2]勋章!$G$7:$G$24,0)),INDEX([2]勋章!$M$7:$M$24,MATCH($B4,[2]勋章!$G$7:$G$24,0)),INDEX([2]勋章!$P$7:$P$24,MATCH($B4,[2]勋章!$G$7:$G$24,0)),INDEX([2]勋章!$S$7:$S$24,MATCH($B4,[2]勋章!$G$7:$G$24,0))) -> 10111 | L4: {=INDEX([2]图纸掉落!$H$4:$H$38,MATCH(H4,[2]图纸掉落!$G$4:$G$38,0))} -> 21001 | M4: 1 | N4: 2 | O4: =INDEX([1]英雄界面!$J$4:$J$41,MATCH(A4,[1]英雄界面!$A$4:$A$41,0))/2 -> 1.5 | P4: 1.6 | Q4: =INT(INDEX([1]等级属性!B$4:B$203,MATCH($AC4,[1]等级属性!$A$4:$A$203,0))*V4/10000) -> 215 | R4: =INT(INDEX([1]等级属性!C$4:C$203,MATCH($AC4,[1]等级属性!$A$4:$A$203,0))*W4/10000) -> 0 | S4: =INT(INDEX([1]等级属性!D$4:D$203,MATCH($AC4,[1]等级属性!$A$4:$A$203,0))*X4/10000) -> 612 | T4: =INT(INDEX([1]等级属性!E$4:E$203,MATCH($AC4,[1]等级属性!$A$4:$A$203,0))*Y4/10000) -> 164 | V4: {=INDEX(单位特点规划!D$2:D$37,MATCH($A4,单位特点规划!$A$2:$A$37,0))} -> 16600 | W4: {=INDEX(单位特点规划!E$2:E$37,MATCH($A4,单位特点规划!$A$2:$A$37,0))} -> 0 | X4: {=INDEX(单位特点规划!F$2:F$37,MATCH($A4,单位特点规划!$A$2:$A$37,0))} -> 15700 | Y4: {=INDEX(单位特点规划!G$2:G$37,MATCH($A4,单位特点规划!$A$2:$A$37,0))} -> 18500 | AA4: =1.93 -> 1.93 | AB4: =INT(INDEX([3]进阶属性!$C$2:$C$19,MATCH(B4,[3]进阶属性!$A$2:$A$19,0))/2*AH4) -> 300 | AC4: =[3]进阶属性!$F3 -> 10 | AD4: =INT((INDEX([3]标准单位!$J$2:$J$201,MATCH($AC4,[3]标准单位!$A$2:$A$201,0))*AE4)/(1-AE4)) -> 0 | AE4: =0 -> 0 | AF4: =AG4/AG4 -> 1 | AG4: =(Q4/AM4*1000+IF(AN4<>"",R4/AN4*1000,0)+S4/3+T4/5)/AH4 -> 143.99524 | AH4: =INDEX([4]Sheet1!H$2:H$36,MATCH($H4,[4]Sheet1!$A$2:$A$36,0)) -> 2 | AI4: =INDEX([4]Sheet1!T$2:T$36,MATCH($H4,[4]Sheet1!$A$2:$A$36,0)) -> 0 | AJ4: =INDEX([4]Sheet1!U$2:U$36,MATCH($H4,[4]Sheet1!$A$2:$A$36,0)) -> 8.4 | AK4: =INDEX([4]Sheet1!V$2:V$36,MATCH($H4,[4]Sheet1!$A$2:$A$36,0)) -> 0 | AL4: =INDEX([4]Sheet1!W$2:W$36,MATCH($H4,[4]Sheet1!$A$2:$A$36,0)) -> 23.809524 | AM4: =INDEX([4]Sheet1!N$2:N$36,MATCH($H4,[4]Sheet1!$A$2:$A$36,0)) -> 4200 | AN4: =INDEX([4]Sheet1!O$2:O$36,MATCH($H4,[4]Sheet1!$A$2:$A$36,0))
A5: 1001 | B5: 2 | C5: ="{"&K5&","&ROUNDUP(M5,0)&"},"&"{"&L5&","&ROUNDUP(N5,0)&"}" -> {10112,5},{21001,5} | D5: 5000 | E5: 17 | F5: ="{1,"&INT(S5*P5)&"},{2,"&INT(Q5*P5)&"},"&IF(R5=0,"","{3,"&INT(R5*P5)&"},")&"{6,"&INT(T5*P5)&"}" -> {1,1192},{2,420},{6,321} | G5: =1 -> 1 | H5: 幻影坦克 | I5: {=INDEX([1]英雄界面!$I$4:$I$41,MATCH(A5,[1]英雄界面!$A$4:$A$41,0))} -> 50 | J5: =1 -> 1 | K5: =CHOOSE(J5,INDEX([2]勋章!$I$7:$I$24,MATCH($B5,[2]勋章!$G$7:$G$24,0)),INDEX([2]勋章!$M$7:$M$24,MATCH($B5,[2]勋章!$G$7:$G$24,0)),INDEX([2]勋章!$P$7:$P$24,MATCH($B5,[2]勋章!$G$7:$G$24,0)),INDEX([2]勋章!$S$7:$S$24,MATCH($B5,[2]勋章!$G$7:$G$24,0))) -> 10112 | L5: {=INDEX([2]图纸掉落!$H$4:$H$38,MATCH(H5,[2]图纸掉落!$G$4:$G$38,0))} -> 21001 | M5: 5 | N5: 5 | O5: =INDEX([1]英雄界面!$J$4:$J$41,MATCH(A5,[1]英雄界面!$A$4:$A$41,0))/2 -> 1.5 | P5: =P4-0.1 -> 1.5 | Q5: =INT(INDEX([1]等级属性!B$4:B$203,MATCH($AC5,[1]等级属性!$A$4:$A$203,0))*V5/10000) -> 280 | R5: =INT(INDEX([1]等级属性!C$4:C$203,MATCH($AC5,[1]等级属性!$A$4:$A$203,0))*W5/10000) -> 0 | S5: =INT(INDEX([1]等级属性!D$4:D$203,MATCH($AC5,[1]等级属性!$A$4:$A$203,0))*X5/10000) -> 795 | T5: =INT(INDEX([1]等级属性!E$4:E$203,MATCH($AC5,[1]等级属性!$A$4:$A$203,0))*Y5/10000) -> 214 | V5: {=INDEX(单位特点规划!D$2:D$37,MATCH($A5,单位特点规划!$A$2:$A$37,0))} -> 16600 | W5: {=INDEX(单位特点规划!E$2:E$37,MATCH($A5,单位特点规划!$A$2:$A$37,0))} -> 0 | X5: {=INDEX(单位特点规划!F$2:F$37,MATCH($A5,单位特点规划!$A$2:$A$37,0))} -> 15700 | Y5: {=INDEX(单位特点规划!G$2:G$37,MATCH($A5,单位特点规划!$A$2:$A$37,0))} -> 18500 | AA5: =1.93 -> 1.93 | AB5: =INT(INDEX([3]进阶属性!$C$2:$C$19,MATCH(B5,[3]进阶属性!$A$2:$A$19,0))/2*AH5) -> 390 | AC5: =[3]进阶属性!$F4 -> 20 | AD5: =INT((INDEX([3]标准单位!$J$2:$J$201,MATCH($AC5,[3]标准单位!$A$2:$A$201,0))*AE5)/(1-AE5)) -> 0 | AE5: =0 -> 0 | AF5: =AG5/AG5 -> 1 | AG5: =(Q5/AM5*1000+IF(AN5<>"",R5/AN5*1000,0)+S5/3+T5/5)/AH5 -> 187.23333 | AH5: {=INDEX([4]Sheet1!H$2:H$36,MATCH($H5,[4]Sheet1!$A$2:$A$36,0))} -> 2 | AI5: =INDEX([4]Sheet1!T$2:T$36,MATCH($H5,[4]Sheet1!$A$2:$A$36,0)) -> 0 | AJ5: =INDEX([4]Sheet1!U$2:U$36,MATCH($H5,[4]Sheet1!$A$2:$A$36,0)) -> 8.4 | AK5: =INDEX([4]Sheet1!V$2:V$36,MATCH($H5,[4]Sheet1!$A$2:$A$36,0)) -> 0 | AL5: =INDEX([4]Sheet1!W$2:W$36,MATCH($H5,[4]Sheet1!$A$2:$A$36,0)) -> 23.809524 | AM5: =INDEX([4]Sheet1!N$2:N$36,MATCH($H5,[4]Sheet1!$A$2:$A$36,0)) -> 4200 | AN5: =INDEX([4]Sheet1!O$2:O$36,MATCH($H5,[4]Sheet1!$A$2:$A$36,0))
A6: 1001 | B6: 3 | C6: ="{"&K6&","&ROUNDUP(M6,0)&"},"&"{"&L6&","&ROUNDUP(N6,0)&"}" -> {10113,7},{21001,8} | D6: 10000 | E6: 26 | F6: ="{1,"&INT(S6*P6)&"},{2,"&INT(Q6*P6)&"},"&IF(R6=0,"","{3,"&INT(R6*P6)&"},")&"{6,"&INT(T6*P6)&"}" -> {1,1443},{2,508},{6,393} | G6: =1 -> 1 | H6: 幻影坦克 | I6: {=INDEX([1]英雄界面!$I$4:$I$41,MATCH(A6,[1]英雄界面!$A$4:$A$41,0))} -> 50 | J6: =1 -> 1 | K6: =CHOOSE(J6,INDEX([2]勋章!$I$7:$I$24,MATCH($B6,[2]勋章!$G$7:$G$24,0)),INDEX([2]勋章!$M$7:$M$24,MATCH($B6,[2]勋章!$G$7:$G$24,0)),INDEX([2]勋章!$P$7:$P$24,MATCH($B6,[2]勋章!$G$7:$G$24,0)),INDEX([2]勋章!$S$7:$S$24,MATCH($B6,[2]勋章!$G$7:$G$24,0))) -> 10113 | L6: {=INDEX([2]图纸掉落!$H$4:$H$38,MATCH(H6,[2]图纸掉落!$G$4:$G$38,0))} -> 21001 | M6: 7 | N6: 8 | O6: =INDEX([1]英雄界面!$J$4:$J$41,MATCH(A6,[1]英雄界面!$A$4:$A$41,0))/2 -> 1.5 | P6: =P5-0.1 -> 1.4 | Q6: =INT(INDEX([1]等级属性!B$4:B$203,MATCH($AC6,[1]等级属性!$A$4:$A$203,0))*V6/10000) -> 363 | R6: =INT(INDEX([1]等级属性!C$4:C$203,MATCH($AC6,[1]等级属性!$A$4:$A$203,0))*W6/10000) -> 0 | S6: =INT(INDEX([1]等级属性!D$4:D$203,MATCH($AC6,[1]等级属性!$A$4:$A$203,0))*X6/10000) -> 1031 | T6: =INT(INDEX([1]等级属性!E$4:E$203,MATCH($AC6,[1]等级属性!$A$4:$A$203,0))*Y6/10000) -> 281 | V6: {=INDEX(单位特点规划!D$2:D$37,MATCH($A6,单位特点规划!$A$2:$A$37,0))} -> 16600 | W6: {=INDEX(单位特点规划!E$2:E$37,MATCH($A6,单位特点规划!$A$2:$A$37,0))} -> 0 | X6: {=INDEX(单位特点规划!F$2:F$37,MATCH($A6,单位特点规划!$A$2:$A$37,0))} -> 15700 | Y6: {=INDEX(单位特点规划!G$2:G$37,MATCH($A6,单位特点规划!$A$2:$A$37,0))} -> 18500 | AA6: =1.93 -> 1.93 | AB6: =INT(INDEX([3]进阶属性!$C$2:$C$19,MATCH(B6,[3]进阶属性!$A$2:$A$19,0))/2*AH6) -> 507 | AC6: =[3]进阶属性!$F5 -> 30 | AD6: =INT((INDEX([3]标准单位!$J$2:$J$201,MATCH($AC6,[3]标准单位!$A$2:$A$201,0))*AE6)/(1-AE6)) -> 0 | AE6: =0 -> 0 | AF6: =AG6/AG6 -> 1 | AG6: =(Q6/AM6*1000+IF(AN6<>"",R6/AN6*1000,0)+S6/3+T6/5)/AH6 -> 243.14762 | AH6: {=INDEX([4]Sheet1!H$2:H$36,MATCH($H6,[4]Sheet1!$A$2:$A$36,0))} -> 2 | AI6: =INDEX([4]Sheet1!T$2:T$36,MATCH($H6,[4]Sheet1!$A$2:$A$36,0)) -> 0 | AJ6: =INDEX([4]Sheet1!U$2:U$36,MATCH($H6,[4]Sheet1!$A$2:$A$36,0)) -> 8.4 | AK6: =INDEX([4]Sheet1!V$2:V$36,MATCH($H6,[4]Sheet1!$A$2:$A$36,0)) -> 0 | AL6: =INDEX([4]Sheet1!W$2:W$36,MATCH($H6,[4]Sheet1!$A$2:$A$36,0)) -> 23.809524 | AM6: =INDEX([4]Sheet1!N$2:N$36,MATCH($H6,[4]Sheet1!$A$2:$A$36,0)) -> 4200 | AN6: =INDEX([4]Sheet1!O$2:O$36,MATCH($H6,[4]Sheet1!$A$2:$A$36,0))
A7: 1001 | B7: 4 | C7: ="{"&K7&","&ROUNDUP(M7,0)&"},"&"{"&L7&","&ROUNDUP(N7,0)&"}" -> {10114,10},{21001,12} | D7: 80000 | E7: 32 | F7: ="{1,"&INT(S7*P7)&"},{2,"&INT(Q7*P7)&"},"&IF(R7=0,"","{3,"&INT(R7*P7)&"},")&"{6,"&INT(T7*P7)&"}" -> {1,1536},{2,540},{6,413} | G7: =1 -> 1 | H7: 幻影坦克 | I7: {=INDEX([1]英雄界面!$I$4:$I$41,MATCH(A7,[1]英雄界面!$A$4:$A$41,0))} -> 50 | J7: =1 -> 1 | K7: =CHOOSE(J7,INDEX([2]勋章!$I$7:$I$24,MATCH($B7,[2]勋章!$G$7:$G$24,0)),INDEX([2]勋章!$M$7:$M$24,MATCH($B7,[2]勋章!$G$7:$G$24,0)),INDEX([2]勋章!$P$7:$P$24,MATCH($B7,[2]勋章!$G$7:$G$24,0)),INDEX([2]勋章!$S$7:$S$24,MATCH($B7,[2]勋章!$G$7:$G$24,0))) -> 10114 | L7: {=INDEX([2]图纸掉落!$H$4:$H$38,MATCH(H7,[2]图纸掉落!$G$4:$G$38,0))} -> 21001 | M7: 10 | N7: 12 | O7: =INDEX([1]英雄界面!$J$4:$J$41,MATCH(A7,[1]英雄界面!$A$4:$A$41,0))/2 -> 1.5 | P7: =P6-0.1 -> 1.3 | Q7: =INT(INDEX([1]等级属性!B$4:B$203,MATCH($AC7,[1]等级属性!$A$4:$A$203,0))*V7/10000) -> 416 | R7: =INT(INDEX([1]等级属性!C$4:C$203,MATCH($AC7,[1]等级属性!$A$4:$A$203,0))*W7/10000) -> 0 | S7: =INT(INDEX([1]等级属性!D$4:D$203,MATCH($AC7,[1]等级属性!$A$4:$A$203,0))*X7/10000) -> 1182 | T7: =INT(INDEX([1]等级属性!E$4:E$203,MATCH($AC7,[1]等级属性!$A$4:$A$203,0))*Y7/10000) -> 318 | V7: {=INDEX(单位特点规划!D$2:D$37,MATCH($A7,单位特点规划!$A$2:$A$37,0))} -> 16600 | W7: {=INDEX(单位特点规划!E$2:E$37,MATCH($A7,单位特点规划!$A$2:$A$37,0))} -> 0 | X7: {=INDEX(单位特点规划!F$2:F$37,MATCH($A7,单位特点规划!$A$2:$A$37,0))} -> 15700 | Y7: {=INDEX(单位特点规划!G$2:G$37,MATCH($A7,单位特点规划!$A$2:$A$37,0))} -> 18500 | AA7: =1.93 -> 1.93 | AB7: =INT(INDEX([3]进阶属性!$C$2:$C$19,MATCH(B7,[3]进阶属性!$A$2:$A$19,0))/2*AH7) -> 657 | AC7: =35 -> 35 | AD7: =INT((INDEX([3]标准单位!$J$2:$J$201,MATCH($AC7,[3]标准单位!$A$2:$A$201,0))*AE7)/(1-AE7)) -> 0 | AE7: =0 -> 0 | AF7: =AG7/AG7 -> 1 | AG7: =(Q7/AM7*1000+IF(AN7<>"",R7/AN7*1000,0)+S7/3+T7/5)/AH7 -> 278.32381 | AH7: {=INDEX([4]Sheet1!H$2:H$36,MATCH($H7,[4]Sheet1!$A$2:$A$36,0))} -> 2 | AI7: =INDEX([4]Sheet1!T$2:T$36,MATCH($H7,[4]Sheet1!$A$2:$A$36,0)) -> 0 | AJ7: =INDEX([4]Sheet1!U$2:U$36,MATCH($H7,[4]Sheet1!$A$2:$A$36,0)) -> 8.4 | AK7: =INDEX([4]Sheet1!V$2:V$36,MATCH($H7,[4]Sheet1!$A$2:$A$36,0)) -> 0 | AL7: =INDEX([4]Sheet1!W$2:W$36,MATCH($H7,[4]Sheet1!$A$2:$A$36,0)) -> 23.809524 | AM7: =INDEX([4]Sheet1!N$2:N$36,MATCH($H7,[4]Sheet1!$A$2:$A$36,0)) -> 4200 | AN7: =INDEX([4]Sheet1!O$2:O$36,MATCH($H7,[4]Sheet1!$A$2:$A$36,0))
A8: 1001 | B8: 5 | C8: ="{"&K8&","&ROUNDUP(M8,0)&"},"&"{"&L8&","&ROUNDUP(N8,0)&"}" -> {10115,15},{21001,15} | D8: 150000 | E8: 37 | F8: ="{1,"&INT(S8*P8)&"},{2,"&INT(Q8*P8)&"},"&IF(R8=0,"","{3,"&INT(R8*P8)&"},")&"{6,"&INT(T8*P8)&"}" -> {1,1604},{2,565},{6,432} | G8: =1 -> 1 | H8: 幻影坦克 | I8: {=INDEX([1]英雄界面!$I$4:$I$41,MATCH(A8,[1]英雄界面!$A$4:$A$41,0))} -> 50 | J8: =1 -> 1 | K8: =CHOOSE(J8,INDEX([2]勋章!$I$7:$I$24,MATCH($B8,[2]勋章!$G$7:$G$24,0)),INDEX([2]勋章!$M$7:$M$24,MATCH($B8,[2]勋章!$G$7:$G$24,0)),INDEX([2]勋章!$P$7:$P$24,MATCH($B8,[2]勋章!$G$7:$G$24,0)),INDEX([2]勋章!$S$7:$S$24,MATCH($B8,[2]勋章!$G$7:$G$24,0))) -> 10115 | L8: {=INDEX([2]图纸掉落!$H$4:$H$38,MATCH(H8,[2]图纸掉落!$G$4:$G$38,0))} -> 21001 | M8: 15 | N8: 15 | O8: =INDEX([1]英雄界面!$J$4:$J$41,MATCH(A8,[1]英雄界面!$A$4:$A$41,0))/2 -> 1.5 | P8: =P7-0.1 -> 1.2 | Q8: =INT(INDEX([1]等级属性!B$4:B$203,MATCH($AC8,[1]等级属性!$A$4:$A$203,0))*V8/10000) -> 471 | R8: =INT(INDEX([1]等级属性!C$4:C$203,MATCH($AC8,[1]等级属性!$A$4:$A$203,0))*W8/10000) -> 0 | S8: =INT(INDEX([1]等级属性!D$4:D$203,MATCH($AC8,[1]等级属性!$A$4:$A$203,0))*X8/10000) -> 1337 | T8: =INT(INDEX([1]等级属性!E$4:E$203,MATCH($AC8,[1]等级属性!$A$4:$A$203,0))*Y8/10000) -> 360 | V8: {=INDEX(单位特点规划!D$2:D$37,MATCH($A8,单位特点规划!$A$2:$A$37,0))} -> 16600 | W8: {=INDEX(单位特点规划!E$2:E$37,MATCH($A8,单位特点规划!$A$2:$A$37,0))} -> 0 | X8: {=INDEX(单位特点规划!F$2:F$37,MATCH($A8,单位特点规划!$A$2:$A$37,0))} -> 15700 | Y8: {=INDEX(单位特点规划!G$2:G$37,MATCH($A8,单位特点规划!$A$2:$A$37,0))} -> 18500 | AA8: =1.93 -> 1.93 | AB8: =INT(INDEX([3]进阶属性!$C$2:$C$19,MATCH(B8,[3]进阶属性!$A$2:$A$19,0))/2*AH8) -> 852 | AC8: 40 | AD8: =INT((INDEX([3]标准单位!$J$2:$J$201,MATCH($AC8,[3]标准单位!$A$2:$A$201,0))*AE8)/(1-AE8)) -> 0 | AE8: =0 -> 0 | AF8: =AG8/AG8 -> 1 | AG8: =(Q8/AM8*1000+IF(AN8<>"",R8/AN8*1000,0)+S8/3+T8/5)/AH8 -> 314.90476 | AH8: {=INDEX([4]Sheet1!H$2:H$36,MATCH($H8,[4]Sheet1!$A$2:$A$36,0))} -> 2 | AI8: =INDEX([4]Sheet1!T$2:T$36,MATCH($H8,[4]Sheet1!$A$2:$A$36,0)) -> 0 | AJ8: =INDEX([4]Sheet1!U$2:U$36,MATCH($H8,[4]Sheet1!$A$2:$A$36,0)) -> 8.4 | AK8: =INDEX([4]Sheet1!V$2:V$36,MATCH($H8,[4]Sheet1!$A$2:$A$36,0)) -> 0 | AL8: =INDEX([4]Sheet1!W$2:W$36,MATCH($H8,[4]Sheet1!$A$2:$A$36,0)) -> 23.809524 | AM8: =INDEX([4]Sheet1!N$2:N$36,MATCH($H8,[4]Sheet1!$A$2:$A$36,0)) -> 4200 | AN8: =INDEX([4]Sheet1!O$2:O$36,MATCH($H8,[4]Sheet1!$A$2:$A$36,0))
A9: 1001 | B9: 6 | C9: ="{"&K9&","&ROUNDUP(M9,0)&"},"&"{"&L9&","&ROUNDUP(N9,0)&"}" -> {10116,20},{21001,16} | D9: 250000 | E9: 42 | F9: ="{1,"&INT(S9*P9)&"},{2,"&INT(Q9*P9)&"},"&IF(R9=0,"","{3,"&INT(R9*P9)&"},")&"{6,"&INT(T9*P9)&"}" -> {1,1688},{2,595},{6,457} | G9: =1 -> 1 | H9: 幻影坦克 | I9: {=INDEX([1]英雄界面!$I$4:$I$41,MATCH(A9,[1]英雄界面!$A$4:$A$41,0))} -> 50 | J9: =1 -> 1 | K9: =CHOOSE(J9,INDEX([2]勋章!$I$7:$I$24,MATCH($B9,[2]勋章!$G$7:$G$24,0)),INDEX([2]勋章!$M$7:$M$24,MATCH($B9,[2]勋章!$G$7:$G$24,0)),INDEX([2]勋章!$P$7:$P$24,MATCH($B9,[2]勋章!$G$7:$G$24,0)),INDEX([2]勋章!$S$7:$S$24,MATCH($B9,[2]勋章!$G$7:$G$24,0))) -> 10116 | L9: {=INDEX([2]图纸掉落!$H$4:$H$38,MATCH(H9,[2]图纸掉落!$G$4:$G$38,0))} -> 21001 | M9: 20 | N9: 16 | O9: =INDEX([1]英雄界面!$J$4:$J$41,MATCH(A9,[1]英雄界面!$A$4:$A$41,0))/2 -> 1.5 | P9: =P8-0.1 -> 1.1 | Q9: =INT(INDEX([1]等级属性!B$4:B$203,MATCH($AC9,[1]等级属性!$A$4:$A$203,0))*V9/10000) -> 541 | R9: =INT(INDEX([1]等级属性!C$4:C$203,MATCH($AC9,[1]等级属性!$A$4:$A$203,0))*W9/10000) -> 0 | S9: =INT(INDEX([1]等级属性!D$4:D$203,MATCH($AC9,[1]等级属性!$A$4:$A$203,0))*X9/10000) -> 1535 | T9: =INT(INDEX([1]等级属性!E$4:E$203,MATCH($AC9,[1]等级属性!$A$4:$A$203,0))*Y9/10000) -> 416 | V9: {=INDEX(单位特点规划!D$2:D$37,MATCH($A9,单位特点规划!$A$2:$A$37,0))} -> 16600 | W9: {=INDEX(单位特点规划!E$2:E$37,MATCH($A9,单位特点规划!$A$2:$A$37,0))} -> 0 | X9: {=INDEX(单位特点规划!F$2:F$37,MATCH($A9,单位特点规划!$A$2:$A$37,0))} -> 15700 | Y9: {=INDEX(单位特点规划!G$2:G$37,MATCH($A9,单位特点规划!$A$2:$A$37,0))} -> 18500 | AA9: =1.93 -> 1.93 | AB9: =INT(INDEX([3]进阶属性!$C$2:$C$19,MATCH(B9,[3]进阶属性!$A$2:$A$19,0))/2*AH9) -> 1107 | AC9: 45 | AD9: =INT((INDEX([3]标准单位!$J$2:$J$201,MATCH($AC9,[3]标准单位!$A$2:$A$201,0))*AE9)/(1-AE9)) -> 0 | AE9: =0 -> 0 | AF9: =AG9/AG9 -> 1 | AG9: =(Q9/AM9*1000+IF(AN9<>"",R9/AN9*1000,0)+S9/3+T9/5)/AH9 -> 361.8381 | AH9: {=INDEX([4]Sheet1!H$2:H$36,MATCH($H9,[4]Sheet1!$A$2:$A$36,0))} -> 2 | AI9: =INDEX([4]Sheet1!T$2:T$36,MATCH($H9,[4]Sheet1!$A$2:$A$36,0)) -> 0 | AJ9: =INDEX([4]Sheet1!U$2:U$36,MATCH($H9,[4]Sheet1!$A$2:$A$36,0)) -> 8.4 | AK9: =INDEX([4]Sheet1!V$2:V$36,MATCH($H9,[4]Sheet1!$A$2:$A$36,0)) -> 0 | AL9: =INDEX([4]Sheet1!W$2:W$36,MATCH($H9,[4]Sheet1!$A$2:$A$36,0)) -> 23.809524 | AM9: =INDEX([4]Sheet1!N$2:N$36,MATCH($H9,[4]Sheet1!$A$2:$A$36,0)) -> 4200 | AN9: =INDEX([4]Sheet1!O$2:O$36,MATCH($H9,[4]Sheet1!$A$2:$A$36,0))
A10: 1001 | B10: 7 | C10: ="{"&K10&","&ROUNDUP(M10,0)&"},"&"{"&L10&","&ROUNDUP(N10,0)&"}" -> {10117,22},{21001,26} | D10: 300000 | E10: 47 | F10: ="{1,"&INT(S10*P10)&"},{2,"&INT(Q10*P10)&"},"&IF(R10=0,"","{3,"&INT(R10*P10)&"},")&"{6,"&INT(T10*P10)&"}" -> {1,1737},{2,612},{6,473} | G10: =1 -> 1 | H10: 幻影坦克 | I10: {=INDEX([1]英雄界面!$I$4:$I$41,MATCH(A10,[1]英雄界面!$A$4:$A$41,0))} -> 50 | J10: =1 -> 1 | K10: =CHOOSE(J10,INDEX([2]勋章!$I$7:$I$24,MATCH($B10,[2]勋章!$G$7:$G$24,0)),INDEX([2]勋章!$M$7:$M$24,MATCH($B10,[2]勋章!$G$7:$G$24,0)),INDEX([2]勋章!$P$7:$P$24,MATCH($B10,[2]勋章!$G$7:$G$24,0)),INDEX([2]勋章!$S$7:$S$24,MATCH($B10,[2]勋章!$G$7:$G$24,0))) -> 10117 | L10: {=INDEX([2]图纸掉落!$H$4:$H$38,MATCH(H10,[2]图纸掉落!$G$4:$G$38,0))} -> 21001 | M10: 22 | N10: 26 | O10: =INDEX([1]英雄界面!$J$4:$J$41,MATCH(A10,[1]英雄界面!$A$4:$A$41,0))/2 -> 1.5 | P10: =P9-0.1 -> 1 | Q10: =INT(INDEX([1]等级属性!B$4:B$203,MATCH($AC10,[1]等级属性!$A$4:$A$203,0))*V10/10000) -> 612 | R10: =INT(INDEX([1]等级属性!C$4:C$203,MATCH($AC10,[1]等级属性!$A$4:$A$203,0))*W10/10000) -> 0 | S10: =INT(INDEX([1]等级属性!D$4:D$203,MATCH($AC10,[1]等级属性!$A$4:$A$203,0))*X10/10000) -> 1737 | T10: =INT(INDEX([1]等级属性!E$4:E$203,MATCH($AC10,[1]等级属性!$A$4:$A$203,0))*Y10/10000) -> 473 | V10: {=INDEX(单位特点规划!D$2:D$37,MATCH($A10,单位特点规划!$A$2:$A$37,0))} -> 16600 | W10: {=INDEX(单位特点规划!E$2:E$37,MATCH($A10,单位特点规划!$A$2:$A$37,0))} -> 0 | X10: {=INDEX(单位特点规划!F$2:F$37,MATCH($A10,单位特点规划!$A$2:$A$37,0))} -> 15700 | Y10: {=INDEX(单位特点规划!G$2:G$37,MATCH($A10,单位特点规划!$A$2:$A$37,0))} -> 18500 | AA10: =1.93 -> 1.93 | AB10: =INT(INDEX([3]进阶属性!$C$2:$C$19,MATCH(B10,[3]进阶属性!$A$2:$A$19,0))/2*AH10) -> 1437 | AC10: 50 | AD10: =INT((INDEX([3]标准单位!$J$2:$J$201,MATCH($AC10,[3]标准单位!$A$2:$A$201,0))*AE10)/(1-AE10)) -> 0 | AE10: =0 -> 0 | AF10: =AG10/AG10 -> 1 | AG10: =(Q10/AM10*1000+IF(AN10<>"",R10/AN10*1000,0)+S10/3+T10/5)/AH10 -> 409.65714 | AH10: {=INDEX([4]Sheet1!H$2:H$36,MATCH($H10,[4]Sheet1!$A$2:$A$36,0))} -> 2 | AI10: =INDEX([4]Sheet1!T$2:T$36,MATCH($H10,[4]Sheet1!$A$2:$A$36,0)) -> 0 | AJ10: =INDEX([4]Sheet1!U$2:U$36,MATCH($H10,[4]Sheet1!$A$2:$A$36,0)) -> 8.4 | AK10: =INDEX([4]Sheet1!V$2:V$36,MATCH($H10,[4]Sheet1!$A$2:$A$36,0)) -> 0 | AL10: =INDEX([4]Sheet1!W$2:W$36,MATCH($H10,[4]Sheet1!$A$2:$A$36,0)) -> 23.809524 | AM10: =INDEX([4]Sheet1!N$2:N$36,MATCH($H10,[4]Sheet1!$A$2:$A$36,0)) -> 4200 | AN10: =INDEX([4]Sheet1!O$2:O$36,MATCH($H10,[4]Sheet1!$A$2:$A$36,0))
A11: 1001 | B11: 8 | C11: ="{"&K11&","&ROUNDUP(M11,0)&"},"&"{"&L11&","&ROUNDUP(N11,0)&"}" -> {10118,25},{21001,29} | D11: 350000 | E11: 52 | F11: ="{1,"&INT(S11*P11)&"},{2,"&INT(Q11*P11)&"},"&IF(R11=0,"","{3,"&INT(R11*P11)&"},")&"{6,"&INT(T11*P11)&"}" -> {1,1997},{2,703},{6,542} | G11: =1 -> 1 | H11: 幻影坦克 | I11: {=INDEX([1]英雄界面!$I$4:$I$41,MATCH(A11,[1]英雄界面!$A$4:$A$41,0))} -> 50 | J11: =1 -> 1 | K11: =CHOOSE(J11,INDEX([2]勋章!$I$7:$I$24,MATCH($B11,[2]勋章!$G$7:$G$24,0)),INDEX([2]勋章!$M$7:$M$24,MATCH($B11,[2]勋章!$G$7:$G$24,0)),INDEX([2]勋章!$P$7:$P$24,MATCH($B11,[2]勋章!$G$7:$G$24,0)),INDEX([2]勋章!$S$7:$S$24,MATCH($B11,[2]勋章!$G$7:$G$24,0))) -> 10118 | L11: {=INDEX([2]图纸掉落!$H$4:$H$38,MATCH(H11,[2]图纸掉落!$G$4:$G$38,0))} -> 21001 | M11: 25 | N11: 29 | O11: =INDEX([1]英雄界面!$J$4:$J$41,MATCH(A11,[1]英雄界面!$A$4:$A$41,0))/2 -> 1.5 | P11: =P10 -> 1 | Q11: =INT(INDEX([1]等级属性!B$4:B$203,MATCH($AC11,[1]等级属性!$A$4:$A$203,0))*V11/10000) -> 703 | R11: =INT(INDEX([1]等级属性!C$4:C$203,MATCH($AC11,[1]等级属性!$A$4:$A$203,0))*W11/10000) -> 0 | S11: =INT(INDEX([1]等级属性!D$4:D$203,MATCH($AC11,[1]等级属性!$A$4:$A$203,0))*X11/10000) -> 1997 | T11: =INT(INDEX([1]等级属性!E$4:E$203,MATCH($AC11,[1]等级属性!$A$4:$A$203,0))*Y11/10000) -> 542 | V11: {=INDEX(单位特点规划!D$2:D$37,MATCH($A11,单位特点规划!$A$2:$A$37,0))} -> 16600 | W11: {=INDEX(单位特点规划!E$2:E$37,MATCH($A11,单位特点规划!$A$2:$A$37,0))} -> 0 | X11: {=INDEX(单位特点规划!F$2:F$37,MATCH($A11,单位特点规划!$A$2:$A$37,0))} -> 15700 | Y11: {=INDEX(单位特点规划!G$2:G$37,MATCH($A11,单位特点规划!$A$2:$A$37,0))} -> 18500 | AA11: =1.93 -> 1.93 | AB11: =INT(INDEX([3]进阶属性!$C$2:$C$19,MATCH(B11,[3]进阶属性!$A$2:$A$19,0))/2*AH11) -> 1866 | AC11: 55 | AD11: =INT((INDEX([3]标准单位!$J$2:$J$201,MATCH($AC11,[3]标准单位!$A$2:$A$201,0))*AE11)/(1-AE11)) -> 0 | AE11: =0 -> 0 | AF11: =AG11/AG11 -> 1 | AG11: =(Q11/AM11*1000+IF(AN11<>"",R11/AN11*1000,0)+S11/3+T11/5)/AH11 -> 470.72381 | AH11: {=INDEX([4]Sheet1!H$2:H$36,MATCH($H11,[4]Sheet1!$A$2:$A$36,0))} -> 2 | AI11: =INDEX([4]Sheet1!T$2:T$36,MATCH($H11,[4]Sheet1!$A$2:$A$36,0)) -> 0 | AJ11: =INDEX([4]Sheet1!U$2:U$36,MATCH($H11,[4]Sheet1!$A$2:$A$36,0)) -> 8.4 | AK11: =INDEX([4]Sheet1!V$2:V$36,MATCH($H11,[4]Sheet1!$A$2:$A$36,0)) -> 0 | AL11: =INDEX([4]Sheet1!W$2:W$36,MATCH($H11,[4]Sheet1!$A$2:$A$36,0)) -> 23.809524 | AM11: =INDEX([4]Sheet1!N$2:N$36,MATCH($H11,[4]Sheet1!$A$2:$A$36,0)) -> 4200 | AN11: =INDEX([4]Sheet1!O$2:O$36,MATCH($H11,[4]Sheet1!$A$2:$A$36,0))
A12: 1001 | B12: 9 | C12: ="{"&K12&","&ROUNDUP(M12,0)&"},"&"{"&L12&","&ROUNDUP(N12,0)&"}" -> {10119,27},{21001,30} | D12: 400000 | E12: 57 | F12: ="{1,"&INT(S12*P12)&"},{2,"&INT(Q12*P12)&"},"&IF(R12=0,"","{3,"&INT(R12*P12)&"},")&"{6,"&INT(T12*P12)&"}" -> {1,2256},{2,795},{6,612} | G12: =1 -> 1 | H12: 幻影坦克 | I12: {=INDEX([1]英雄界面!$I$4:$I$41,MATCH(A12,[1]英雄界面!$A$4:$A$41,0))} -> 50 | J12: =1 -> 1 | K12: =CHOOSE(J12,INDEX([2]勋章!$I$7:$I$24,MATCH($B12,[2]勋章!$G$7:$G$24,0)),INDEX([2]勋章!$M$7:$M$24,MATCH($B12,[2]勋章!$G$7:$G$24,0)),INDEX([2]勋章!$P$7:$P$24,MATCH($B12,[2]勋章!$G$7:$G$24,0)),INDEX([2]勋章!$S$7:$S$24,MATCH($B12,[2]勋章!$G$7:$G$24,0))) -> 10119 | L12: {=INDEX([2]图纸掉落!$H$4:$H$38,MATCH(H12,[2]图纸掉落!$G$4:$G$38,0))} -> 21001 | M12: 27 | N12: 30 | O12: =INDEX([1]英雄界面!$J$4:$J$41,MATCH(A12,[1]英雄界面!$A$4:$A$41,0))/2 -> 1.5 | P12: =P11 -> 1 | Q12: =INT(INDEX([1]等级属性!B$4:B$203,MATCH($AC12,[1]等级属性!$A$4:$A$203,0))*V12/10000) -> 795 | R12: =INT(INDEX([1]等级属性!C$4:C$203,MATCH($AC12,[1]等级属性!$A$4:$A$203,0))*W12/10000) -> 0 | S12: =INT(INDEX([1]等级属性!D$4:D$203,MATCH($AC12,[1]等级属性!$A$4:$A$203,0))*X12/10000) -> 2256 | T12: =INT(INDEX([1]等级属性!E$4:E$203,MATCH($AC12,[1]等级属性!$A$4:$A$203,0))*Y12/10000) -> 612 | V12: {=INDEX(单位特点规划!D$2:D$37,MATCH($A12,单位特点规划!$A$2:$A$37,0))} -> 16600 | W12: {=INDEX(单位特点规划!E$2:E$37,MATCH($A12,单位特点规划!$A$2:$A$37,0))} -> 0 | X12: {=INDEX(单位特点规划!F$2:F$37,MATCH($A12,单位特点规划!$A$2:$A$37,0))} -> 15700 | Y12: {=INDEX(单位特点规划!G$2:G$37,MATCH($A12,单位特点规划!$A$2:$A$37,0))} -> 18500 | AA12: =1.93 -> 1.93 | AB12: =INT(INDEX([3]进阶属性!$C$2:$C$19,MATCH(B12,[3]进阶属性!$A$2:$A$19,0))/2*AH12) -> 2424 | AC12: 60 | AD12: =INT((INDEX([3]标准单位!$J$2:$J$201,MATCH($AC12,[3]标准单位!$A$2:$A$201,0))*AE12)/(1-AE12)) -> 0 | AE12: =0 -> 0 | AF12: =AG12/AG12 -> 1 | AG12: =(Q12/AM12*1000+IF(AN12<>"",R12/AN12*1000,0)+S12/3+T12/5)/AH12 -> 531.84286 | AH12: {=INDEX([4]Sheet1!H$2:H$36,MATCH($H12,[4]Sheet1!$A$2:$A$36,0))} -> 2 | AI12: =INDEX([4]Sheet1!T$2:T$36,MATCH($H12,[4]Sheet1!$A$2:$A$36,0)) -> 0 | AJ12: =INDEX([4]Sheet1!U$2:U$36,MATCH($H12,[4]Sheet1!$A$2:$A$36,0)) -> 8.4 | AK12: =INDEX([4]Sheet1!V$2:V$36,MATCH($H12,[4]Sheet1!$A$2:$A$36,0)) -> 0 | AL12: =INDEX([4]Sheet1!W$2:W$36,MATCH($H12,[4]Sheet1!$A$2:$A$36,0)) -> 23.809524 | AM12: =INDEX([4]Sheet1!N$2:N$36,MATCH($H12,[4]Sheet1!$A$2:$A$36,0)) -> 4200 | AN12: =INDEX([4]Sheet1!O$2:O$36,MATCH($H12,[4]Sheet1!$A$2:$A$36,0))
A13: 1001 | B13: 10 | C13: ="{"&K13&","&ROUNDUP(M13,0)&"},"&"{"&L13&","&ROUNDUP(N13,0)&"}" -> {10120,30},{21001,45} | D13: 450000 | E13: 62 | F13: ="{1,"&INT(S13*P13)&"},{2,"&INT(Q13*P13)&"},"&IF(R13=0,"","{3,"&INT(R13*P13)&"},")&"{6,"&INT(T13*P13)&"}" -> {1,2590},{2,913},{6,704} | G13: =1 -> 1 | H13: 幻影坦克 | I13: {=INDEX([1]英雄界面!$I$4:$I$41,MATCH(A13,[1]英雄界面!$A$4:$A$41,0))} -> 50 | J13: =1 -> 1 | K13: =CHOOSE(J13,INDEX([2]勋章!$I$7:$I$24,MATCH($B13,[2]勋章!$G$7:$G$24,0)),INDEX([2]勋章!$M$7:$M$24,MATCH($B13,[2]勋章!$G$7:$G$24,0)),INDEX([2]勋章!$P$7:$P$24,MATCH($B13,[2]勋章!$G$7:$G$24,0)),INDEX([2]勋章!$S$7:$S$24,MATCH($B13,[2]勋章!$G$7:$G$24,0))) -> 10120 | L13: {=INDEX([2]图纸掉落!$H$4:$H$38,MATCH(H13,[2]图纸掉落!$G$4:$G$38,0))} -> 21001 | M13: 30 | N13: 45 | O13: =INDEX([1]英雄界面!$J$4:$J$41,MATCH(A13,[1]英雄界面!$A$4:$A$41,0))/2 -> 1.5 | P13: =P12 -> 1 | Q13: =INT(INDEX([1]等级属性!B$4:B$203,MATCH($AC13,[1]等级属性!$A$4:$A$203,0))*V13/10000) -> 913 | R13: =INT(INDEX([1]等级属性!C$4:C$203,MATCH($AC13,[1]等级属性!$A$4:$A$203,0))*W13/10000) -> 0 | S13: =INT(INDEX([1]等级属性!D$4:D$203,MATCH($AC13,[1]等级属性!$A$4:$A$203,0))*X13/10000) -> 2590 | T13: =INT(INDEX([1]等级属性!E$4:E$203,MATCH($AC13,[1]等级属性!$A$4:$A$203,0))*Y13/10000) -> 704 | V13: {=INDEX(单位特点规划!D$2:D$37,MATCH($A13,单位特点规划!$A$2:$A$37,0))} -> 16600 | W13: {=INDEX(单位特点规划!E$2:E$37,MATCH($A13,单位特点规划!$A$2:$A$37,0))} -> 0 | X13: {=INDEX(单位特点规划!F$2:F$37,MATCH($A13,单位特点规划!$A$2:$A$37,0))} -> 15700 | Y13: {=INDEX(单位特点规划!G$2:G$37,MATCH($A13,单位特点规划!$A$2:$A$37,0))} -> 18500 | AA13: =1.93 -> 1.93 | AB13: =INT(INDEX([3]进阶属性!$C$2:$C$19,MATCH(B13,[3]进阶属性!$A$2:$A$19,0))/2*AH13) -> 3150 | AC13: 65 | AD13: =INT((INDEX([3]标准单位!$J$2:$J$201,MATCH($AC13,[3]标准单位!$A$2:$A$201,0))*AE13)/(1-AE13)) -> 0 | AE13: =0 -> 0 | AF13: =AG13/AG13 -> 1 | AG13: =(Q13/AM13*1000+IF(AN13<>"",R13/AN13*1000,0)+S13/3+T13/5)/AH13 -> 610.75714 | AH13: {=INDEX([4]Sheet1!H$2:H$36,MATCH($H13,[4]Sheet1!$A$2:$A$36,0))} -> 2 | AI13: =INDEX([4]Sheet1!T$2:T$36,MATCH($H13,[4]Sheet1!$A$2:$A$36,0)) -> 0 | AJ13: =INDEX([4]Sheet1!U$2:U$36,MATCH($H13,[4]Sheet1!$A$2:$A$36,0)) -> 8.4 | AK13: =INDEX([4]Sheet1!V$2:V$36,MATCH($H13,[4]Sheet1!$A$2:$A$36,0)) -> 0 | AL13: =INDEX([4]Sheet1!W$2:W$36,MATCH($H13,[4]Sheet1!$A$2:$A$36,0)) -> 23.809524 | AM13: =INDEX([4]Sheet1!N$2:N$36,MATCH($H13,[4]Sheet1!$A$2:$A$36,0)) -> 4200 | AN13: =INDEX([4]Sheet1!O$2:O$36,MATCH($H13,[4]Sheet1!$A$2:$A$36,0))
A14: 1001 | B14: 11 | C14: ="{"&K14&","&ROUNDUP(M14,0)&"},"&"{"&L14&","&ROUNDUP(N14,0)&"}" -> {10121,32},{21001,61} | D14: 500000 | E14: 67 | F14: ="{1,"&INT(S14*P14)&"},{2,"&INT(Q14*P14)&"},"&IF(R14=0,"","{3,"&INT(R14*P14)&"},")&"{6,"&INT(T14*P14)&"}" -> {1,2929},{2,1032},{6,797} | G14: =1 -> 1 | H14: 幻影坦克 | I14: {=INDEX([1]英雄界面!$I$4:$I$41,MATCH(A14,[1]英雄界面!$A$4:$A$41,0))} -> 50 | J14: =1 -> 1 | K14: =CHOOSE(J14,INDEX([2]勋章!$I$7:$I$24,MATCH($B14,[2]勋章!$G$7:$G$24,0)),INDEX([2]勋章!$M$7:$M$24,MATCH($B14,[2]勋章!$G$7:$G$24,0)),INDEX([2]勋章!$P$7:$P$24,MATCH($B14,[2]勋章!$G$7:$G$24,0)),INDEX([2]勋章!$S$7:$S$24,MATCH($B14,[2]勋章!$G$7:$G$24,0))) -> 10121 | L14: {=INDEX([2]图纸掉落!$H$4:$H$38,MATCH(H14,[2]图纸掉落!$G$4:$G$38,0))} -> 21001 | M14: 32 | N14: 61 | O14: =INDEX([1]英雄界面!$J$4:$J$41,MATCH(A14,[1]英雄界面!$A$4:$A$41,0))/2 -> 1.5 | P14: =P13 -> 1 | Q14: =INT(INDEX([1]等级属性!B$4:B$203,MATCH($AC14,[1]等级属性!$A$4:$A$203,0))*V14/10000) -> 1032 | R14: =INT(INDEX([1]等级属性!C$4:C$203,MATCH($AC14,[1]等级属性!$A$4:$A$203,0))*W14/10000) -> 0 | S14: =INT(INDEX([1]等级属性!D$4:D$203,MATCH($AC14,[1]等级属性!$A$4:$A$203,0))*X14/10000) -> 2929 | T14: =INT(INDEX([1]等级属性!E$4:E$203,MATCH($AC14,[1]等级属性!$A$4:$A$203,0))*Y14/10000) -> 797 | V14: {=INDEX(单位特点规划!D$2:D$37,MATCH($A14,单位特点规划!$A$2:$A$37,0))} -> 16600 | W14: {=INDEX(单位特点规划!E$2:E$37,MATCH($A14,单位特点规划!$A$2:$A$37,0))} -> 0 | X14: {=INDEX(单位特点规划!F$2:F$37,MATCH($A14,单位特点规划!$A$2:$A$37,0))} -> 15700 | Y14: {=INDEX(单位特点规划!G$2:G$37,MATCH($A14,单位特点规划!$A$2:$A$37,0))} -> 18500 | AA14: =1.93 -> 1.93 | AB14: =INT(INDEX([3]进阶属性!$C$2:$C$19,MATCH(B14,[3]进阶属性!$A$2:$A$19,0))/2*AH14) -> 4095 | AC14: 70 | AD14: =INT((INDEX([3]标准单位!$J$2:$J$201,MATCH($AC14,[3]标准单位!$A$2:$A$201,0))*AE14)/(1-AE14)) -> 0 | AE14: =0 -> 0 | AF14: =AG14/AG14 -> 1 | AG14: =(Q14/AM14*1000+IF(AN14<>"",R14/AN14*1000,0)+S14/3+T14/5)/AH14 -> 690.72381 | AH14: {=INDEX([4]Sheet1!H$2:H$36,MATCH($H14,[4]Sheet1!$A$2:$A$36,0))} -> 2 | AI14: =INDEX([4]Sheet1!T$2:T$36,MATCH($H14,[4]Sheet1!$A$2:$A$36,0)) -> 0 | AJ14: =INDEX([4]Sheet1!U$2:U$36,MATCH($H14,[4]Sheet1!$A$2:$A$36,0)) -> 8.4 | AK14: =INDEX([4]Sheet1!V$2:V$36,MATCH($H14,[4]Sheet1!$A$2:$A$36,0)) -> 0 | AL14: =INDEX([4]Sheet1!W$2:W$36,MATCH($H14,[4]Sheet1!$A$2:$A$36,0)) -> 23.809524 | AM14: =INDEX([4]Sheet1!N$2:N$36,MATCH($H14,[4]Sheet1!$A$2:$A$36,0)) -> 4200 | AN14: =INDEX([4]Sheet1!O$2:O$36,MATCH($H14,[4]Sheet1!$A$2:$A$36,0))
A15: 1001 | B15: 12 | C15: ="{"&K15&","&ROUNDUP(M15,0)&"},"&"{"&L15&","&ROUNDUP(N15,0)&"}" -> {10122,35},{21001,66} | D15: 550000 | E15: 72 | F15: ="{1,"&INT(S15*P15)&"},{2,"&INT(Q15*P15)&"},"&IF(R15=0,"","{3,"&INT(R15*P15)&"},")&"{6,"&INT(T15*P15)&"}" -> {1,3367},{2,1186},{6,915} | G15: =1 -> 1 | H15: 幻影坦克 | I15: {=INDEX([1]英雄界面!$I$4:$I$41,MATCH(A15,[1]英雄界面!$A$4:$A$41,0))} -> 50 | J15: =1 -> 1 | K15: =CHOOSE(J15,INDEX([2]勋章!$I$7:$I$24,MATCH($B15,[2]勋章!$G$7:$G$24,0)),INDEX([2]勋章!$M$7:$M$24,MATCH($B15,[2]勋章!$G$7:$G$24,0)),INDEX([2]勋章!$P$7:$P$24,MATCH($B15,[2]勋章!$G$7:$G$24,0)),INDEX([2]勋章!$S$7:$S$24,MATCH($B15,[2]勋章!$G$7:$G$24,0))) -> 10122 | L15: {=INDEX([2]图纸掉落!$H$4:$H$38,MATCH(H15,[2]图纸掉落!$G$4:$G$38,0))} -> 21001 | M15: 35 | N15: 66 | O15: =INDEX([1]英雄界面!$J$4:$J$41,MATCH(A15,[1]英雄界面!$A$4:$A$41,0))/2 -> 1.5 | P15: =P14 -> 1 | Q15: =INT(INDEX([1]等级属性!B$4:B$203,MATCH($AC15,[1]等级属性!$A$4:$A$203,0))*V15/10000) -> 1186 | R15: =INT(INDEX([1]等级属性!C$4:C$203,MATCH($AC15,[1]等级属性!$A$4:$A$203,0))*W15/10000) -> 0 | S15: =INT(INDEX([1]等级属性!D$4:D$203,MATCH($AC15,[1]等级属性!$A$4:$A$203,0))*X15/10000) -> 3367 | T15: =INT(INDEX([1]等级属性!E$4:E$203,MATCH($AC15,[1]等级属性!$A$4:$A$203,0))*Y15/10000) -> 915 | V15: {=INDEX(单位特点规划!D$2:D$37,MATCH($A15,单位特点规划!$A$2:$A$37,0))} -> 16600 | W15: {=INDEX(单位特点规划!E$2:E$37,MATCH($A15,单位特点规划!$A$2:$A$37,0))} -> 0 | X15: {=INDEX(单位特点规划!F$2:F$37,MATCH($A15,单位特点规划!$A$2:$A$37,0))} -> 15700 | Y15: {=INDEX(单位特点规划!G$2:G$37,MATCH($A15,单位特点规划!$A$2:$A$37,0))} -> 18500 | AA15: =1.93 -> 1.93 | AB15: =INT(INDEX([3]进阶属性!$C$2:$C$19,MATCH(B15,[3]进阶属性!$A$2:$A$19,0))/2*AH15) -> 5322 | AC15: 75 | AD15: =INT((INDEX([3]标准单位!$J$2:$J$201,MATCH($AC15,[3]标准单位!$A$2:$A$201,0))*AE15)/(1-AE15)) -> 0 | AE15: =0 -> 0 | AF15: =AG15/AG15 -> 1 | AG15: =(Q15/AM15*1000+IF(AN15<>"",R15/AN15*1000,0)+S15/3+T15/5)/AH15 -> 793.85714 | AH15: {=INDEX([4]Sheet1!H$2:H$36,MATCH($H15,[4]Sheet1!$A$2:$A$36,0))} -> 2 | AI15: =INDEX([4]Sheet1!T$2:T$36,MATCH($H15,[4]Sheet1!$A$2:$A$36,0)) -> 0 | AJ15: =INDEX([4]Sheet1!U$2:U$36,MATCH($H15,[4]Sheet1!$A$2:$A$36,0)) -> 8.4 | AK15: =INDEX([4]Sheet1!V$2:V$36,MATCH($H15,[4]Sheet1!$A$2:$A$36,0)) -> 0 | AL15: =INDEX([4]Sheet1!W$2:W$36,MATCH($H15,[4]Sheet1!$A$2:$A$36,0)) -> 23.809524 | AM15: =INDEX([4]Sheet1!N$2:N$36,MATCH($H15,[4]Sheet1!$A$2:$A$36,0)) -> 4200 | AN15: =INDEX([4]Sheet1!O$2:O$36,MATCH($H15,[4]Sheet1!$A$2:$A$36,0))
A16: 1001 | B16: 13 | C16: ="{"&K16&","&ROUNDUP(M16,0)&"},"&"{"&L16&","&ROUNDUP(N16,0)&"}" -> {10123,37},{21001,70} | D16: 600000 | E16: 77 | F16: ="{1,"&INT(S16*P16)&"},{2,"&INT(Q16*P16)&"},"&IF(R16=0,"","{3,"&INT(R16*P16)&"},")&"{6,"&INT(T16*P16)&"}" -> {1,3805},{2,1341},{6,1036} | G16: =1 -> 1 | H16: 幻影坦克 | I16: {=INDEX([1]英雄界面!$I$4:$I$41,MATCH(A16,[1]英雄界面!$A$4:$A$41,0))} -> 50 | J16: =1 -> 1 | K16: =CHOOSE(J16,INDEX([2]勋章!$I$7:$I$24,MATCH($B16,[2]勋章!$G$7:$G$24,0)),INDEX([2]勋章!$M$7:$M$24,MATCH($B16,[2]勋章!$G$7:$G$24,0)),INDEX([2]勋章!$P$7:$P$24,MATCH($B16,[2]勋章!$G$7:$G$24,0)),INDEX([2]勋章!$S$7:$S$24,MATCH($B16,[2]勋章!$G$7:$G$24,0))) -> 10123 | L16: {=INDEX([2]图纸掉落!$H$4:$H$38,MATCH(H16,[2]图纸掉落!$G$4:$G$38,0))} -> 21001 | M16: 37 | N16: 70 | O16: =INDEX([1]英雄界面!$J$4:$J$41,MATCH(A16,[1]英雄界面!$A$4:$A$41,0))/2 -> 1.5 | P16: =P15 -> 1 | Q16: =INT(INDEX([1]等级属性!B$4:B$203,MATCH($AC16,[1]等级属性!$A$4:$A$203,0))*V16/10000) -> 1341 | R16: =INT(INDEX([1]等级属性!C$4:C$203,MATCH($AC16,[1]等级属性!$A$4:$A$203,0))*W16/10000) -> 0 | S16: =INT(INDEX([1]等级属性!D$4:D$203,MATCH($AC16,[1]等级属性!$A$4:$A$203,0))*X16/10000) -> 3805 | T16: =INT(INDEX([1]等级属性!E$4:E$203,MATCH($AC16,[1]等级属性!$A$4:$A$203,0))*Y16/10000) -> 1036 | V16: {=INDEX(单位特点规划!D$2:D$37,MATCH($A16,单位特点规划!$A$2:$A$37,0))} -> 16600 | W16: {=INDEX(单位特点规划!E$2:E$37,MATCH($A16,单位特点规划!$A$2:$A$37,0))} -> 0 | X16: {=INDEX(单位特点规划!F$2:F$37,MATCH($A16,单位特点规划!$A$2:$A$37,0))} -> 15700 | Y16: {=INDEX(单位特点规划!G$2:G$37,MATCH($A16,单位特点规划!$A$2:$A$37,0))} -> 18500 | AA16: =1.93 -> 1.93 | AB16: =INT(INDEX([3]进阶属性!$C$2:$C$19,MATCH(B16,[3]进阶属性!$A$2:$A$19,0))/2*AH16) -> 6918 | AC16: 80 | AD16: =INT((INDEX([3]标准单位!$J$2:$J$201,MATCH($AC16,[3]标准单位!$A$2:$A$201,0))*AE16)/(1-AE16)) -> 0 | AE16: =0 -> 0 | AF16: =AG16/AG16 -> 1 | AG16: =(Q16/AM16*1000+IF(AN16<>"",R16/AN16*1000,0)+S16/3+T16/5)/AH16 -> 897.40952 | AH16: {=INDEX([4]Sheet1!H$2:H$36,MATCH($H16,[4]Sheet1!$A$2:$A$36,0))} -> 2 | AI16: =INDEX([4]Sheet1!T$2:T$36,MATCH($H16,[4]Sheet1!$A$2:$A$36,0)) -> 0 | AJ16: =INDEX([4]Sheet1!U$2:U$36,MATCH($H16,[4]Sheet1!$A$2:$A$36,0)) -> 8.4 | AK16: =INDEX([4]Sheet1!V$2:V$36,MATCH($H16,[4]Sheet1!$A$2:$A$36,0)) -> 0 | AL16: =INDEX([4]Sheet1!W$2:W$36,MATCH($H16,[4]Sheet1!$A$2:$A$36,0)) -> 23.809524 | AM16: =INDEX([4]Sheet1!N$2:N$36,MATCH($H16,[4]Sheet1!$A$2:$A$36,0)) -> 4200 | AN16: =INDEX([4]Sheet1!O$2:O$36,MATCH($H16,[4]Sheet1!$A$2:$A$36,0))
