Workbook

Sheet monster
A1: 怪物id 1：战役副本（类型1+章2+节2+怪2） 2：精英副本【命名规则同战役副本】 3：日常副本（类型1+章2+节2+怪2） 4：组队副本（类型1+星2+节2+怪2）【礼包单位的测试：41+三位编码+怪物2】 51：野外怪物（51+类型1+等级2+怪2）【类型，1为主力怪物，2为防空补充】 6：世界BOSS 7：测试 8：地图摆件（地图8+章2+节2+怪1） 9：抵抗侵略 61：世界基地 75：竞技场防御建筑 76：公会副本（76+两位章节数+1位训练场+2位怪物 77：将领副本（77+两位关卡数+3位怪物 | B1: 名字 | C1: shareDataID | D1: 所占的人口 代码会把属性名变成： populace | E1: 主武器攻击 代码会把属性名变成： main_atk | F1: 副武器攻击 代码会把属性名变成： minor_atk | G1: 防御 代码会把属性名变成： def | H1: 生命 代码会把属性名变成： hp | I1: 等级 代码会把属性名变成： level | J1: 精英(0非,1是) | K1: 是否特别介绍(0非,1是)
A2: id | C2: s | D2: p | E2: a | F2: b | G2: d | H2: h | I2: l | J2: k | K2: r
A3: int | B3: string | C3: int | D3: int | E3: int | F3: int | G3: int | H3: int | I3: int | J3: int | K3: int
A4: 1010107 | B4: 沙包横 | C4: 20006 | D4: 0 | E4: 0 | F4: 0 | G4: 0 | H4: 5000 | I4: 1
A5: 8888888 | B5: 飞行单位 | C5: 10121 | D5: 0 | E5: 42 | F5: 0 | G5: 0 | H5: 500 | I5: 27
A6: 7712001 | B6: 法师 | C6: 10130 | D6: 4 | E6: 63 | F6: 0 | G6: 0 | H6: 500 | I6: 90
A7: 1020804 | B7: 奶妈 | C7: 61000 | D7: 3 | E7: 50 | F7: 0 | G7: 0 | H7: 500 | I7: 6
A8: 1030505 | B8: 攻城器 | C8: 10117 | D8: 3 | E8: 42 | F8: 0 | G8: 0 | H8: 500 | I8: 8
A9: 1060203 | B9: 野怪 | C9: 10134 | D9: 1 | E9: 32 | F9: 0 | G9: 0 | H9: 500 | I9: 27
A10: 1080808 | B10: 近战肉盾 | C10: 10110 | D10: 6 | E10: 21 | F10: 0 | G10: 0 | H10: 500 | I10: 47
A11: 1030912 | B11: 弓箭塔 | C11: 20105 | D11: 0 | E11: 26 | F11: 0 | G11: 0 | H11: 750 | I11: 9
A12: 1020504 | B12: 雷电塔 | C12: 20101 | D12: 0 | E12: 53 | F12: 0 | G12: 0 | H12: 750 | I12: 4
A13: 7608220 | B13: 冰冻塔 | C13: 20102 | D13: 0 | E13: 53 | F13: 0 | G13: 0 | H13: 750 | I13: 95
A14: 7610206 | B14: 投石车 | C14: 10116 | D14: 4 | E14: 105 | F14: 0 | G14: 0 | H14: 1500 | I14: 125
A15: 7700009 | B15: 法师塔 | C15: 20104 | D15: 0 | E15: 53 | F15: 0 | G15: 0 | H15: 750 | I15: 35
... A25: 9999975 | B25: 城墙三 | C25: 70023 | D25: 0 | E25: 0 | F25: 0 | G25: 0 | H25: 15000 | I25: 1
A26: 9999996 | B26: 世界BOSS | C26: 70004 | D26: 0 | E26: 0 | F26: 0 | G26: 0 | H26: 0 | I26: 0 | J26: 0
A27: 8000001 | B27: 雷神奥丁 | C27: 60005 | D27: 4 | E27: 42 | F27: 280 | G27: 0 | H27: 4500 | I27: 44 | J27: 1
A28: 8000002 | B28: Marv | C28: 60006 | D28: 4 | E28: 84 | F28: 560 | G28: 0 | H28: 4500 | I28: 44 | J28: 1
A29: 8000003 | B29: 阿库斯 | C29: 60007 | D29: 4 | E29: 28 | F29: 560 | G29: 0 | H29: 4500 | I29: 44 | J29: 1
A30: 8000004 | B30: 帝王机甲 | C30: 60008 | D30: 4 | E30: 84 | F30: 840 | G30: 0 | H30: 4500 | I30: 44 | J30: 1
A31: 9999999 | B31: 测试沙包（建筑） | C31: 99999 | D31: 0 | E31: 0 | F31: 0 | G31: 0 | H31: 10000 | I31: 1
A32: 9999998 | B32: 测试沙包（士兵） | C32: 99998 | D32: 0 | E32: 0 | F32: 0 | G32: 0 | H32: 10000 | I32: 1
A33: 9999997 | B33: 测试用进攻沙包 | C33: 10121 | D33: 6 | E33: 5 | F33: 0 | G33: 0 | H33: 9999999 | I33: 47
A34: 8888889 | B34: 治疗兵 | C34: 61000 | D34: 3 | E34: 80 | F34: 100 | G34: 0 | H34: 1000 | I34: 6
A35: 6000001 | B35: 雷神 | C35: 60001 | D35: 4 | E35: 21 | F35: 140 | G35: 0 | H35: 2500 | I35: 44 | J35: 1
A36: 6000002 | B36: Marv | C36: 60002 | D36: 4 | E36: 42 | F36: 280 | G36: 0 | H36: 2500 | I36: 44 | J36: 1
A37: 6000003 | B37: 阿库斯 | C37: 60003 | D37: 4 | E37: 14 | F37: 280 | G37: 0 | H37: 2500 | I37: 44 | J37: 1
A38: 6000004 | B38: 帝王机甲 | C38: 60004 | D38: 4 | E38: 42 | F38: 420 | G38: 0 | H38: 2500 | I38: 44 | J38: 1
A39: 6000005 | B39: 肉盾(进攻) | C39: 50001 | D39: 6 | E39: 56 | F39: 0 | G39: 0 | H39: 3000 | I39: 47
A40: 6000006 | B40: 近战DPS(进攻) | C40: 50004 | D40: 1 | E40: 84 | F40: 0 | G40: 0 | H40: 1500 | I40: 27
A41: 6000007 | B41: 飞行(进攻) | C41: 50005 | D41: 0 | E41: 56 | F41: 0 | G41: 0 | H41: 4000 | I41: 27
A42: 6000008 | B42: 法师(进攻) | C42: 50003 | D42: 4 | E42: 168 | F42: 100 | G42: 0 | H42: 2000 | I42: 90
A43: 6000009 | B43: 奶妈(进攻) | C43: 50006 | D43: 3 | E43: 120 | F43: 100 | G43: 0 | H43: 2000 | I43: 6
A44: 6000010 | B44: 攻城器(进攻) | C44: 50002 | D44: 3 | E44: 168 | F44: 0 | G44: 0 | H44: 2000 | I44: 8

Sheet Sheet5

Sheet shareData
A1: shareDataId | B1: 名字 | C1: 资源id | D1: 是否有武器资源 | E1: 头像 | F1: 一次连续出多少单位 | G1: 单位类型 0、机械的（飞机坦克）默认 1、建筑 2、生物（人类、狗） | H1: 必填 单位所在范围 0、陆地 1、空中 2、在地面上但可受到空中伤害 | I1: 飞行高度 | J1: 在地图上的占位 (默认是占一格) 写2（表示长宽2,占4格） 写3（表示长宽3,占9格） | K1: 路障 额外占用可行走区域 {-1,-1},{1,1} 相对于路障点周围的点 | L1: 所占的人口 | M1: 主武器伤害对装甲 2500,2500,2500,7500,10000,10000,6500,6500,6000,2500,10000 10000为分母 | N1: 副武器伤害对装甲 加成 | O1: 必填 攻击空中陆地 0、陆地 1、空中 2、全部 | P1: 装甲类型 1无盔甲、2英雄盔甲、3重型盔甲、4轻型装甲、5中型装甲、6重型装甲、7建筑:木质材料、8建筑:钢铁材料、9建筑:钢筋混凝土材料、10轻型特殊装甲、11重型特殊装甲 | Q1: 目标优先级(填职业) | R1: 忽略列表（填职业） | S1: 炮弹值(飞机有效) 武器类型,炮弹值 1,3表示主武器炮弹值3 2,4表示副武器炮弹值4 副武器炮弹值消耗完了不会回家装弹 | T1: 移动速度(走一格多少毫秒) 为-1时,不能移动,对时空军团兵来说该值为传送后每一格距离僵直时间 | U1: 转身速度 (多少毫秒转一圈) 飞机移动速度越快转圈速度也要越快 | V1: 主武器攻击范围 【最大攻击距离，最小攻击距离（可不填）】 10,4 (表示最大攻击10，最小攻4) 9 （表示最大攻击9，最小可不填） | W1: 副武器攻击范围 【最大攻击距离，最小攻击距离（可不填）】 10,4 (表示最大攻击10，最小攻4) 9 （表示最大攻击9，最小可不填） | X1: 普攻攻击间隔(ms) | Y1: 技能攻击间隔 | Z1: eye范围 10,4 (表示视野10，最小视野4) 注：最小视野范围可不填 | AA1: 普攻 | AB1: 技能发招顺序 | AC1: 技能 | AD1: 技能发招顺序 | AE1: s音效 可以有多个 "hero1001" 或者 "hero1001","hero1002" | AF1: 一直加在英雄身上的特效 | AG1: 移动特效 | AH1: 待机特效 | AI1: 死亡特效 | AJ1: 尸体特效 死亡后留在场景 | AK1: 死亡技能 | AL1: 职业 1、近战肉盾； 2、近战DPS； 3、飞机； 4、远程DPS； 5、奶妈； 6、攻城器； 7、城墙； 8、基地； 9、弓箭塔； 10、法师塔； 11、雷电塔； 12、投石车； 13、防空炮； 14、冰冻塔； 15、地面英雄； 16、飞行英雄 | AM1: 单位出场动画 总部有 法国巨炮有 | AN1: 类型 0:地面士兵 1：飞行士兵 2：英雄 3：建筑 | AO1: 野外对应的场景资源
A2: id | B2: name | C2: res | D2: atkRes | E2: head | F2: heroNum | G2: heroType | H2: scope | I2: flyHeight | J2: posLength | K2: occupy | L2: populace | M2: atkRate | N2: atkRate_1 | O2: atkScope | P2: defType | Q2: priority | R2: ignore | S2: bombNum | T2: speed | U2: turnSpeed | W2: atkRange_1 | X2: main_atkCD | Y2: minor_atkCD | AA2: skills | AB2: skillTurn | AC2: skills_1 | AD2: skillTurn_1 | AE2: effect | AF2: heroMagic | AG2: moveMagic | AH2: standMagic | AI2: dieMagic | AJ2: corpseMagic | AK2: dieSkill | AL2: career | AM2: comeOutRes | AN2: arm | AO2: sRes
A3: int | B3: string | C3: string | D3: int | E3: int | F3: int | G3: int | H3: int | I3: int | J3: int | K3: array | L3: int | M3: array | N3: array | O3: array | P3: int | Q3: array | R3: array | S3: array | T3: int | U3: int | V3: array | W3: array | X3: int | Y3: int | Z3: array | AA3: array | AB3: array | AC3: array | AD3: array | AE3: array | AF3: array | AG3: array | AH3: array | AI3: array | AJ3: int | AK3: array | AL3: int | AM3: string | AN3: int | AO3: int
A4: 10110 | B4: 未来坦克 | C4: hero/FutureTank00 | G4: 0 | H4: 2 | J4: 1 | L4: 6 | M4: 2500,2500,2500,7500,10000,10000,10000,10000,7000,6000,10000 | O4: 0 | P4: 6 | Q4: {1,2,4,5,6,8,9,10,11,12,13,14,15},{7},{8} | R4: 3,16 | T4: 600 | V4: 2 | X4: 2000 | Z4: 30 | AA4: 70001 | AB4: 1 | AE4: "s_SUHamme_VoiAttacke" | AI4: 50003 | AL4: 1 | AN4: 0 | AO4: 1010
A5: 10116 | B5: 法国巨炮 | C5: hero/GrandCannon00 | D5: 1 | G5: 0 | H5: 2 | J5: 1 | L5: 4 | M5: 10000,10000,10000,7500,7500,7500,10000,10000,5000,10000,10000 | O5: 0 | P5: 7 | Q5: {15},{1,2,4,5,6,8,9,10,11,12,13,14},{7},{8} | R5: 3,16 | T5: -1 | V5: 15 | X5: 3000 | Z5: 15 | AA5: 70002 | AB5: 1 | AE5: "s_OpenFire" | AI5: 50004 | AL5: 12 | AN5: 3 | AO5: 2010
A6: 10117 | B6: V3火箭 | C6: hero/V3rocket00 | G6: 0 | H6: 2 | J6: 1 | L6: 3 | M6: 10000,10000,10000,22500,15000,15000,60000,60000,60000,30000,30000 | O6: 0 | P6: 4 | Q6: {9,10,11,12,13,14},{7},{8},{1,2,3,4,5,6,15,16} | T6: 1200 | V6: 18 | X6: 6000 | Z6: 30 | AA6: 70003 | AB6: 1 | AE6: "s_v3build" | AI6: 50003 | AL6: 6 | AN6: 0 | AO6: 2006
A7: 10130 | B7: 尤里X法师 | C7: hero/fashi00 | G7: 2 | H7: 2 | J7: 1 | L7: 4 | M7: 10000,10000,10000,5000,5000,5000,0,0,0,0,0 | O7: 2 | P7: 6 | Q7: {1,2,3,4,5,6,9,10,11,12,13,14,15,16},{7},{8} | T7: 1400 | V7: 13 | X7: 1000 | Z7: 30 | AA7: 70004 | AB7: 1 | AE7: "s_makeItGrow" | AI7: 50003 | AL7: 4 | AN7: 0 | AO7: 4004
A8: 10132 | B8: 娜塔莎 | C8: hero/Natasha | G8: 2 | H8: 2 | J8: 1 | L8: 3 | M8: 10000,10000,10000,0,0,0,100,100,100,100,10000 | N8: 0,0,0,10000,10000,10000,10000,10000,10000,10000,10000 | O8: 2 | P8: 2 | Q8: {1,2,3,4,5,6,9,10,11,12,13,14,15,16},{7},{8} | T8: 1600 | V8: 8 | X8: 1000 | Z8: 30 | AA8: 70005 | AB8: 1 | AE8: "s_LetRockAndRoll" | AI8: 50005 | AL8: 5 | AN8: 0 | AO8: 4003
A9: 10134 | B9: 恐怖机器人 | C9: hero/TerrorDrone00 | G9: 0 | H9: 2 | J9: 1 | L9: 1 | M9: 10000,8000,8000,5000,2500,2500,7500,5000,2500,10000,10000 | N9: 2000,2000,2000,10000,5000,10000,1000,1000,1000,10000,10000 | O9: 0 | P9: 4 | Q9: {1,2,4,5,6,9,10,11,12,13,14,15},{7},{8} | R9: 3,16 | T9: 800 | V9: 3 | X9: 1200 | Z9: 30 | AA9: 70006 | AB9: 1 | AE9: "s_Siryessir" | AI9: 50003 | AL9: 2 | AN9: 0 | AO9: 2002
A10: 10121 | B10: 武装直升机 | C10: hero/helicopter00 | G10: 0 | H10: 1 | I10: 130 | J10: 1 | L10: 2 | M10: 10000,10000,10000,10000,10000,10000,10000,10000,7500,10000,10000 | O10: 2 | P10: 4 | Q10: {1,2,3,4,5,6,9,10,11,12,13,14,15,16},{7},{8} | T10: 1000 | V10: 6 | X10: 1500 | Z10: 30 | AA10: 70007 | AB10: 1 | AE10: "s_Airtransportready" | AI10: 50006,50007 | AL10: 3 | AN10: 1 | AO10: 3003
A11: 20001 | B11: 总部 | C11: hero/buildingBase01 | G11: 1 | H11: 2 | J11: 3 | K11: {0,0},{0,1},{1,0},{1,1},{-1,0},{-1,1},{0,-1},{1,-1},{-1,-1} | L11: 0 | O11: 0 | P11: 7 | T11: -1 | V11: 0 | X11: 9999999 | AA11: 0 | AI11: 50008,50009 | AL11: 8 | AN11: 3 | AO11: 6
A12: 20002 | B12: 总部 | C12: hero/buildingBase01 | G12: 1 | H12: 2 | J12: 2 | K12: {0,0},{0,1},{1,0},{1,1} | L12: 0 | O12: 0 | P12: 7 | T12: -1 | V12: 0 | X12: 9999999 | AA12: 0 | AI12: 50008,50009 | AL12: 8 | AN12: 3 | AO12: 7
A13: 20006 | B13: 沙包横 | C13: hero/obstacleSandbagbunkers02 | G13: 1 | H13: 2 | J13: 1 | K13: {1,0},{0,0} | L13: 0 | O13: 0 | P13: 7 | T13: -1 | V13: 0 | X13: 9999999 | AA13: 0 | AI13: 50010 | AL13: 7 | AN13: 3 | AO13: 11
A14: 20007 | B14: 城墙 | C14: hero/Wall | G14: 1 | H14: 2 | J14: 1 | K14: {0,1},{0,-1},{0,0} | L14: 0 | O14: 0 | P14: 7 | T14: -1 | V14: 0 | X14: 9999999 | AA14: 0 | AI14: 50010 | AL14: 7 | AN14: 3 | AO14: 11
A15: 20008 | B15: 城门 | C15: hero/WallDoor | G15: 1 | H15: 2 | J15: 1 | K15: {0,1},{0,-1},{0,0} | L15: 0 | O15: 0 | P15: 7 | T15: -1 | V15: 0 | X15: 9999999 | AA15: 0 | AI15: 50010 | AL15: 7 | AN15: 3 | AO15: 11
A16: 20009 | B16: 地对空飞弹 | C16: hero/Missileplatform00 | D16: 1 | G16: 0 | H16: 2 | J16: 1 | K16: {0,0} | L16: 0 | M16: 10000,8000,7000,5000,3000,1000,1000,500,300,20000,5000 | O16: 1 | P16: 7 | Q16: {3,16} | R16: 1,2,4,5,6,7,8,9,10,11,12,13,14,15 | T16: -1 | V16: 10 | X16: 1000 | Z16: 10 | AA16: 70008 | AB16: 1 | AI16: 50011 | AL16: 13 | AN16: 3 | AO16: 2
A17: 20101 | B17: 磁暴线圈 | C17: hero/TeslaCoil00 | G17: 1 | H17: 2 | J17: 1 | K17: {0,0} | L17: 0 | M17: 30000,30000,30000,5000,5000,5000,5000,5000,5000,20000,10000 | O17: 0 | P17: 7 | Q17: {1,2,4,5,6,9,10,11,12,13,14,15},{7},{8} | R17: 3,16 | T17: -1 | V17: 10 | X17: 1200 | Z17: 10 | AA17: 70009 | AB17: 1 | AF17: 72009 | AI17: 50010 | AL17: 11 | AN17: 3 | AO17: 2
A18: 20102 | B18: 心灵控制塔 | C18: hero/MindControlTower00 | G18: 1 | H18: 2 | J18: 1 | K18: {0,0} | L18: 0 | M18: 10000,8000,7000,5000,3000,1000,1000,500,300,20000,5000 | O18: 0 | P18: 7 | Q18: {1,2,4,5,6,9,10,11,12,13,14,15},{7},{8} | R18: 3,16 | T18: -1 | V18: 10 | X18: 1800 | Z18: 10 | AA18: 70010 | AB18: 1 | AF18: 71010 | AI18: 50010 | AL18: 14 | AN18: 3 | AO18: 2
A19: 20104 | B19: 光棱塔 | C19: hero/PrismTower00 | G19: 1 | H19: 2 | J19: 1 | K19: {0,0} | L19: 0 | M19: 10000,8000,7000,5000,3000,1000,1000,500,300,20000,5000 | O19: 0 | P19: 7 | Q19: {1,2,4,5,6,9,10,11,12,13,14,15},{7},{8} | R19: 3,16 | T19: -1 | V19: 10 | X19: 1500 | Z19: 10 | AA19: 70011 | AB19: 1 | AI19: 50010 | AL19: 10 | AN19: 3 | AO19: 2
A20: 20105 | B20: 盖特机炮 | C20: hero/GatlingCannon00 | G20: 0 | H20: 2 | J20: 1 | K20: {0,0} | L20: 0 | M20: 20000,16000,14000,3000,2000,800,1000,500,300,20000,5000 | O20: 2 | P20: 4 | Q20: {1,2,3,4,5,6,9,10,11,12,13,14,15,16},{7},{8} | T20: -1 | V20: 10 | X20: 1000 | Z20: 10 | AA20: 70012 | AB20: 1 | AE20: "s_easyTarget" | AI20: 50003 | AL20: 9 | AN20: 3 | AO20: 1009
A21: 70001 | B21: 城墙 | C21: hero/chengqiang | G21: 1 | H21: 2 | J21: 1 | K21: {0,0},{1,0} | L21: 0 | O21: 0 | P21: 7 | T21: -1 | V21: 0 | X21: 9999999 | AA21: 0 | AI21: 50010 | AL21: 7 | AN21: 3 | AO21: 11
A22: 71001 | B22: 城墙（无死亡特效） | C22: hero/chengqiang | G22: 1 | H22: 2 | J22: 1 | K22: {0,0},{1,0} | L22: 0 | O22: 0 | P22: 7 | T22: -1 | V22: 0 | X22: 9999999 | AA22: 0 | AL22: 7 | AN22: 3 | AO22: 11
A23: 70002 | B23: 城墙 | C23: hero/chengqiang1 | G23: 1 | H23: 2 | J23: 1 | K23: {0,0},{1,0} | L23: 0 | O23: 0 | P23: 7 | T23: -1 | V23: 0 | X23: 9999999 | AA23: 0 | AI23: 50010 | AL23: 7 | AN23: 3 | AO23: 11
A24: 70013 | B24: 城墙二 | C24: hero/chengqiang2 | G24: 1 | H24: 2 | J24: 1 | K24: {0,1},{0,-1},{0,0},{1,1},{1,-1},{1,0} | L24: 0 | O24: 0 | P24: 7 | T24: -1 | V24: 0 | X24: 9999999 | AA24: 0 | AI24: 50010 | AL24: 7 | AN24: 3 | AO24: 11
A25: 70023 | B25: 城墙三 | C25: hero/chengqiang2 | G25: 1 | H25: 2 | J25: 1 | K25: {0,1},{0,-1},{0,0},{1,1},{1,-1},{1,0} | L25: 0 | O25: 0 | P25: 7 | T25: -1 | V25: 0 | X25: 9999999 | AA25: 0 | AI25: 50010 | AL25: 7 | AN25: 3 | AO25: 11
A26: 70003 | B26: 城墙一 | C26: hero/chengqiang2 | G26: 1 | H26: 2 | J26: 1 | K26: {0,1},{0,-1},{0,0},{1,1},{1,-1},{1,0} | L26: 0 | O26: 0 | P26: 7 | T26: -1 | V26: 0 | X26: 9999999 | AA26: 0 | AI26: 50010 | AL26: 7 | AN26: 3 | AO26: 11
A27: 70004 | B27: 世界BOSS | C27: hero/SkyShip | D27: 1 | G27: 0 | H27: 1 | J27: 2 | O27: 1 | T27: -1 | V27: 0 | X27: 9999999 | AA27: 0 | AI27: 111 | AL27: 7 | AN27: 1 | AO27: 4008
A28: 60001 | B28: 雷神 | C28: hero/Aoding00 | E28: 106004 | G28: 0 | H28: 2 | J28: 1 | L28: 1 | M28: 10000,10000,8000,10000,10000,10000,3000,2000,2000,10000,10000 | N28: 2000,2000,2000,10000,5000,10000,1000,1000,1000,10000,10000 | O28: 2 | P28: 6 | Q28: {1,2,3,4,5,6,9,10,11,12,13,14,15,16},{7},{8} | T28: 1000 | V28: 6 | W28: 10 | X28: 1200 | Y28: 15000 | Z28: 30 | AA28: 60001 | AB28: 1 | AC28: 60011 | AD28: 1 | AF28: 80002 | AI28: 50003 | AL28: 15 | AN28: 2 | AO28: 1011
A29: 60002 | B29: 谢尔曼 | C29: hero/Marv00 | D29: 1 | E29: 106008 | G29: 0 | H29: 2 | J29: 1 | L29: 1 | M29: 10000,10000,8000,10000,10000,10000,3000,2000,2000,10000,10000 | N29: 2000,2000,2000,10000,5000,10000,1000,1000,1000,10000,10000 | O29: 2 | P29: 6 | Q29: {1,2,3,4,5,6,9,10,11,12,13,14,15,16},{7},{8} | T29: 1000 | V29: 8 | W29: 10 | X29: 1200 | Y29: 10000 | Z29: 30 | AA29: 60002 | AB29: 1 | AC29: 60012 | AD29: 1 | AF29: 80002 | AI29: 50003 | AL29: 15 | AN29: 2 | AO29: 1011
A30: 60003 | B30: 战斧 | C30: hero/Akusi00 | D30: 1 | E30: 106002 | G30: 0 | H30: 1 | I30: 130 | J30: 1 | L30: 1 | M30: 10000,10000,8000,10000,10000,10000,3000,2000,2000,10000,10000 | N30: 2000,2000,2000,10000,5000,10000,1000,1000,1000,10000,10000 | O30: 2 | P30: 6 | Q30: {1,2,3,4,5,6,9,10,11,12,13,14,15,16},{7},{8} | S30: 1,3 | T30: 1000 | V30: 10 | W30: 10 | X30: 1500 | Y30: 10000 | Z30: 30 | AA30: 60003 | AB30: 1 | AC30: 60013 | AD30: 1 | AF30: 80002 | AI30: 50003 | AL30: 16 | AN30: 1 | AO30: 1011
A31: 60004 | B31: 机甲巨人 | C31: hero/King00 | E31: 106006 | G31: 0 | H31: 2 | J31: 1 | L31: 1 | M31: 10000,10000,8000,10000,10000,10000,3000,2000,2000,10000,10000 | N31: 2000,2000,2000,10000,5000,10000,1000,1000,1000,10000,10000 | O31: 2 | P31: 6 | Q31: {1,2,4,5,6,9,10,11,12,13,14,15},{7},{8} | R31: 3,16 | T31: 400 | V31: 1 | W31: 2 | X31: 2000 | Y31: 5000 | Z31: 30 | AA31: 60004 | AB31: 1 | AC31: 60015 | AD31: 1 | AF31: 80002 | AI31: 50003 | AL31: 15 | AN31: 2 | AO31: 1011
A32: 99999 | B32: 测试沙包（建筑） | C32: hero/chengqiang | G32: 1 | H32: 2 | J32: 1 | K32: {0,0} | L32: 0 | O32: 0 | P32: 7 | T32: -1 | V32: 0 | X32: 9999999 | AA32: 0 | AI32: 50010 | AL32: 9 | AN32: 3 | AO32: 11
A33: 99998 | B33: 测试沙包（士兵） | C33: hero/chengqiang | G33: 2 | H33: 2 | J33: 1 | K33: {0,0} | L33: 0 | O33: 0 | P33: 7 | T33: -1 | V33: 0 | X33: 9999999 | AA33: 0 | AI33: 50010 | AL33: 1 | AN33: 3 | AO33: 11
A34: 61000 | B34: 治疗兵 | C34: hero/CureMan00 | G34: 2 | H34: 2 | J34: 1 | L34: 3 | M34: 10000,10000,10000,0,0,0,100,100,100,100,10000 | N34: 0,0,0,10000,10000,10000,10000,10000,10000,10000,10000 | O34: 2 | P34: 2 | Q34: {1,2,3,4,5,6,9,10,11,12,13,14,15,16},{7},{8} | T34: 600 | V34: 16 | X34: 1000 | Z34: 30 | AA34: 71013 | AB34: 1 | AE34: "s_LetRockAndRoll" | AI34: 50005 | AL34: 5 | AN34: 0 | AO34: 4003
A35: 60005 | B35: 雷神 | C35: hero/Aoding00 | E35: 106003 | G35: 0 | H35: 2 | J35: 2 | L35: 1 | M35: 10000,10000,8000,10000,10000,10000,3000,2000,2000,10000,10000 | N35: 2000,2000,2000,10000,5000,10000,1000,1000,1000,10000,10000 | O35: 2 | P35: 6 | Q35: {1,2,3,4,5,6,9,10,11,12,13,14,15,16},{7},{8} | T35: 600 | V35: 10 | W35: 10 | X35: 1200 | Y35: 15000 | Z35: 30 | AA35: 60001 | AB35: 1 | AC35: 60011 | AD35: 1 | AF35: 80001 | AI35: 50003 | AL35: 15 | AN35: 2 | AO35: 1011
A36: 60006 | B36: 谢尔曼 | C36: hero/Marv00 | D36: 1 | E36: 106007 | G36: 0 | H36: 2 | J36: 2 | L36: 1 | M36: 10000,10000,8000,10000,10000,10000,3000,2000,2000,10000,10000 | N36: 2000,2000,2000,10000,5000,10000,1000,1000,1000,10000,10000 | O36: 2 | P36: 6 | Q36: {1,2,3,4,5,6,9,10,11,12,13,14,15,16},{7},{8} | T36: 600 | V36: 8 | W36: 10 | X36: 1200 | Y36: 10000 | Z36: 30 | AA36: 60002 | AB36: 1 | AC36: 60012 | AD36: 1 | AF36: 80001 | AI36: 50003 | AL36: 15 | AN36: 2 | AO36: 1011
A37: 60007 | B37: 战斧 | C37: hero/Akusi00 | D37: 1 | E37: 106001 | G37: 0 | H37: 1 | I37: 130 | J37: 2 | L37: 1 | M37: 10000,10000,8000,10000,10000,10000,3000,2000,2000,10000,10000 | N37: 2000,2000,2000,10000,5000,10000,1000,1000,1000,10000,10000 | O37: 2 | P37: 6 | Q37: {1,2,3,4,5,6,9,10,11,12,13,14,15,16},{7},{8} | S37: 1,3 | T37: 600 | V37: 6 | W37: 10 | X37: 1500 | Y37: 10000 | Z37: 30 | AA37: 60003 | AB37: 1 | AC37: 60013 | AD37: 1 | AF37: 80001 | AI37: 50003 | AL37: 16 | AN37: 1 | AO37: 1011
A38: 60008 | B38: 机甲巨人 | C38: hero/King00 | E38: 106005 | G38: 0 | H38: 2 | J38: 2 | L38: 1 | M38: 10000,10000,8000,10000,10000,10000,3000,2000,2000,10000,10000 | N38: 2000,2000,2000,10000,5000,10000,1000,1000,1000,10000,10000 | O38: 2 | P38: 6 | Q38: {1,2,4,5,6,9,10,11,12,13,14,15},{7},{8} | R38: 3,16 | T38: 600 | V38: 1 | W38: 2 | X38: 2000 | Y38: 5000 | Z38: 30 | AA38: 60004 | AB38: 1 | AC38: 60015 | AD38: 1 | AF38: 80001 | AI38: 50003 | AL38: 15 | AN38: 2 | AO38: 1011
A39: 50001 | B39: 未来坦克 | C39: hero/FutureTank00 | G39: 0 | H39: 2 | J39: 1 | L39: 1 | M39: 2500,2500,2500,7500,10000,10000,10000,10000,7000,6000,10000 | O39: 0 | P39: 6 | Q39: {1,2,4,5,6,8,9,10,11,12,13,14,15},{7},{8} | R39: 3,16 | T39: 600 | V39: 2 | X39: 2000 | Z39: 30 | AA39: 70001 | AB39: 1 | AE39: "s_SUHamme_VoiAttacke" | AI39: 50003 | AL39: 1 | AN39: 0 | AO39: 1010
A40: 50002 | B40: V3火箭 | C40: hero/V3rocket00 | G40: 0 | H40: 2 | J40: 1 | L40: 3 | M40: 10000,10000,10000,22500,15000,15000,60000,60000,60000,30000,30000 | O40: 0 | P40: 4 | Q40: {9,10,11,12,13,14},{7},{8},{1,2,3,4,5,6,15,16} | T40: 1200 | V40: 18 | X40: 6000 | Z40: 30 | AA40: 71003 | AB40: 1 | AE40: "s_v3build" | AI40: 50003 | AL40: 6 | AN40: 0 | AO40: 2006
...

Sheet levelToDungeon
A1: 章 | B1: 节 | C1: 能力等级 | D1: 装备系数 | H1: 章 | I1: 能力等级 | J1: 进入等级
A2: 1 | B2: 1 | C2: 1 | H2: 1 | I2: 1 | J2: 1
A3: =A2 -> 1 | B3: 2 | C3: 1 | H3: 2 | I3: 10 | J3: 5
A4: =A3 -> 1 | B4: 3 | C4: 1 | H4: 3 | I4: 20 | J4: 10
A5: =A4 -> 1 | B5: 4 | C5: 2 | H5: 4 | I5: 30 | J5: 15
A6: =A5 -> 1 | B6: 5 | C6: 2 | H6: 5 | I6: 40 | J6: 20
A7: =A6 -> 1 | B7: 6 | C7: 3 | H7: 6 | I7: 50 | J7: 25
A8: =A7 -> 1 | B8: 7 | C8: 3 | H8: 7 | I8: 60 | J8: 30
A9: =A8 -> 1 | B9: 8 | C9: 4 | H9: 8 | I9: 70 | J9: 35
A10: =A9 -> 1 | B10: 9 | C10: 3 | H10: 9 | I10: 80 | J10: 40
A11: =A10 -> 1 | B11: 10 | C11: 3 | H11: 10 | I11: 90 | J11: 45
A12: =A11 -> 1 | B12: 11 | C12: 4 | H12: 11 | I12: 100 | J12: 50
A13: =A12 -> 1 | B13: 12 | C13: 6 | H13: 12 | I13: 110 | J13: 55
A14: =A2+1 -> 2 | B14: =B2 -> 1 | C14: 2 | H14: 13 | I14: 120 | J14: 60
A15: =A3+1 -> 2 | B15: =B3 -> 2 | C15: 2 | H15: 14 | I15: 130 | J15: 65
A16: =A4+1 -> 2 | B16: =B4 -> 3 | C16: 3 | H16: 15 | I16: 140 | J16: 70
A17: =A5+1 -> 2 | B17: =B5 -> 4 | C17: 3 | H17: 16 | I17: 150 | J17: 75
A18: =A6+1 -> 2 | B18: =B6 -> 5 | C18: 4
A19: =A7+1 -> 2 | B19: =B7 -> 6 | C19: 4
A20: =A8+1 -> 2 | B20: =B8 -> 7 | C20: 4
A21: =A9+1 -> 2 | B21: =B9 -> 8 | C21: 6
A22: =A10+1 -> 2 | B22: =B10 -> 9 | C22: 5
A23: =A11+1 -> 2 | B23: =B11 -> 10 | C23: 6
A24: =A12+1 -> 2 | B24: =B12 -> 11 | C24: 6
A25: =A13+1 -> 2 | B25: =B13 -> 12 | C25: 9
A26: =A14+1 -> 3 | B26: =B14 -> 1 | C26: 5
A27: =A15+1 -> 3 | B27: =B15 -> 2 | C27: 6
A28: =A16+1 -> 3 | B28: =B16 -> 3 | C28: 7
A29: =A17+1 -> 3 | B29: =B17 -> 4 | C29: 7
... A97: =A85+1 -> 8 | B97: =B85 -> 12 | C97: 51
A98: =A86+1 -> 9 | B98: =B86 -> 1 | C98: =C97-1 -> 50
A99: =A87+1 -> 9 | B99: =B87 -> 2 | C99: =C98+1 -> 51
A100: =A88+1 -> 9 | B100: =B88 -> 3 | C100: =C99+1 -> 52
A101: =A89+1 -> 9 | B101: =B89 -> 4 | C101: =C100+1 -> 53
A102: =A90+1 -> 9 | B102: =B90 -> 5 | C102: =C101+1 -> 54
A103: =A91+1 -> 9 | B103: =B91 -> 6 | C103: =C102+1 -> 55
A104: =A92+1 -> 9 | B104: =B92 -> 7 | C104: =C103+1 -> 56
A105: =A93+1 -> 9 | B105: =B93 -> 8 | C105: =C104+2 -> 58
A106: =A94+1 -> 9 | B106: =B94 -> 9 | C106: =C105-1 -> 57
A107: =A95+1 -> 9 | B107: =B95 -> 10 | C107: =C106+1 -> 58
...

Sheet 属性系数
A1: ID | B1: 名字 | C1: 主攻击系数 | D1: 副攻击系数 | E1: 生命系数 | F1: 防御系数 | G1: 飞行与否 | H1: 英雄id | I1: 主攻击系数 | J1: 副攻击系数 | K1: 生命系数 | L1: 防御系数
A2: 10000 | B2: 空母战机 | C2: =I2 -> 1.25 | D2: =J2 -> 0 | E2: =K2 -> 0.59 | F2: =L2 -> 0.89 | G2: TRUE | H2: 3005 | I2: =INDEX([1]单位特点规划!D$2:D$36,MATCH($H2,[1]单位特点规划!$A$2:$A$36,0))/10000 -> 1.25 | J2: =INDEX([1]单位特点规划!E$2:E$36,MATCH($H2,[1]单位特点规划!$A$2:$A$36,0))/10000 -> 0 | K2: =INDEX([1]单位特点规划!F$2:F$36,MATCH($H2,[1]单位特点规划!$A$2:$A$36,0))/10000 -> 0.59 | L2: =INDEX([1]单位特点规划!G$2:G$36,MATCH($H2,[1]单位特点规划!$A$2:$A$36,0))/10000 -> 0.89
A3: 10101 | B3: 美国大兵 | C3: =I3 -> 0.22 | D3: =J3 -> 0.45 | E3: =K3 -> 0.45 | F3: =L3 -> 0.32 | G3: FALSE | H3: {=INDEX([1]单位特点规划!$A$2:$A$37,MATCH(B3,[1]单位特点规划!$B$2:$B$37,0))} -> 4001 | I3: =INDEX([1]单位特点规划!D$2:D$36,MATCH($H3,[1]单位特点规划!$A$2:$A$36,0))/10000 -> 0.22 | J3: =INDEX([1]单位特点规划!E$2:E$36,MATCH($H3,[1]单位特点规划!$A$2:$A$36,0))/10000 -> 0.45 | K3: =INDEX([1]单位特点规划!F$2:F$36,MATCH($H3,[1]单位特点规划!$A$2:$A$36,0))/10000 -> 0.45 | L3: =INDEX([1]单位特点规划!G$2:G$36,MATCH($H3,[1]单位特点规划!$A$2:$A$36,0))/10000 -> 0.32
A4: 10102 | B4: 盖特坦克 | C4: =I4 -> 0.975 | D4: =J4 -> 0 | E4: =K4 -> 0.56 | F4: =L4 -> 1.05 | G4: FALSE | H4: {=INDEX([1]单位特点规划!$A$2:$A$37,MATCH(B4,[1]单位特点规划!$B$2:$B$37,0))} -> 1009 | I4: =INDEX([1]单位特点规划!D$2:D$36,MATCH($H4,[1]单位特点规划!$A$2:$A$36,0))/10000 -> 0.975 | J4: =INDEX([1]单位特点规划!E$2:E$36,MATCH($H4,[1]单位特点规划!$A$2:$A$36,0))/10000 -> 0 | K4: =INDEX([1]单位特点规划!F$2:F$36,MATCH($H4,[1]单位特点规划!$A$2:$A$36,0))/10000 -> 0.56 | L4: =INDEX([1]单位特点规划!G$2:G$36,MATCH($H4,[1]单位特点规划!$A$2:$A$36,0))/10000 -> 1.05
A5: 10103 | B5: 灰熊坦克 | C5: =I5 -> 0.84 | D5: =J5 -> 0 | E5: =K5 -> 1.24 | F5: =L5 -> 1.5 | G5: FALSE | H5: {=INDEX([1]单位特点规划!$A$2:$A$37,MATCH(B5,[1]单位特点规划!$B$2:$B$37,0))} -> 1005 | I5: =INDEX([1]单位特点规划!D$2:D$36,MATCH($H5,[1]单位特点规划!$A$2:$A$36,0))/10000 -> 0.84 | J5: =INDEX([1]单位特点规划!E$2:E$36,MATCH($H5,[1]单位特点规划!$A$2:$A$36,0))/10000 -> 0 | K5: =INDEX([1]单位特点规划!F$2:F$36,MATCH($H5,[1]单位特点规划!$A$2:$A$36,0))/10000 -> 1.24 | L5: =INDEX([1]单位特点规划!G$2:G$36,MATCH($H5,[1]单位特点规划!$A$2:$A$36,0))/10000 -> 1.5
A6: 10104 | B6: 犀牛坦克 | C6: =I6 -> 0.9 | D6: =J6 -> 0 | E6: =K6 -> 1 | F6: =L6 -> 1 | G6: FALSE | H6: {=INDEX([1]单位特点规划!$A$2:$A$37,MATCH(B6,[1]单位特点规划!$B$2:$B$37,0))} -> 1003 | I6: =INDEX([1]单位特点规划!D$2:D$36,MATCH($H6,[1]单位特点规划!$A$2:$A$36,0))/10000 -> 0.9 | J6: =INDEX([1]单位特点规划!E$2:E$36,MATCH($H6,[1]单位特点规划!$A$2:$A$36,0))/10000 -> 0 | K6: =INDEX([1]单位特点规划!F$2:F$36,MATCH($H6,[1]单位特点规划!$A$2:$A$36,0))/10000 -> 1 | L6: =INDEX([1]单位特点规划!G$2:G$36,MATCH($H6,[1]单位特点规划!$A$2:$A$36,0))/10000 -> 1
A7: 10105 | B7: 坦克杀手 | C7: =I7 -> 2 | D7: =J7 -> 0 | E7: =K7 -> 1.51 | F7: =L7 -> 1.93 | G7: FALSE | H7: {=INDEX([1]单位特点规划!$A$2:$A$37,MATCH(B7,[1]单位特点规划!$B$2:$B$37,0))} -> 1004 | I7: =INDEX([1]单位特点规划!D$2:D$36,MATCH($H7,[1]单位特点规划!$A$2:$A$36,0))/10000 -> 2 | J7: =INDEX([1]单位特点规划!E$2:E$36,MATCH($H7,[1]单位特点规划!$A$2:$A$36,0))/10000 -> 0 | K7: =INDEX([1]单位特点规划!F$2:F$36,MATCH($H7,[1]单位特点规划!$A$2:$A$36,0))/10000 -> 1.51 | L7: =INDEX([1]单位特点规划!G$2:G$36,MATCH($H7,[1]单位特点规划!$A$2:$A$36,0))/10000 -> 1.93
A8: 10106 | B8: 遥控坦克 | C8: =I8 -> 1.22 | D8: =J8 -> 0 | E8: =K8 -> 1.5 | F8: =L8 -> 1.1 | G8: FALSE | H8: {=INDEX([1]单位特点规划!$A$2:$A$37,MATCH(B8,[1]单位特点规划!$B$2:$B$37,0))} -> 1008 | I8: =INDEX([1]单位特点规划!D$2:D$36,MATCH($H8,[1]单位特点规划!$A$2:$A$36,0))/10000 -> 1.22 | J8: =INDEX([1]单位特点规划!E$2:E$36,MATCH($H8,[1]单位特点规划!$A$2:$A$36,0))/10000 -> 0 | K8: =INDEX([1]单位特点规划!F$2:F$36,MATCH($H8,[1]单位特点规划!$A$2:$A$36,0))/10000 -> 1.5 | L8: =INDEX([1]单位特点规划!G$2:G$36,MATCH($H8,[1]单位特点规划!$A$2:$A$36,0))/10000 -> 1.1
A9: 10107 | B9: 磁能坦克 | C9: =I9 -> 1.53 | D9: =J9 -> 0 | E9: =K9 -> 1.35 | F9: =L9 -> 1.87 | G9: FALSE | H9: {=INDEX([1]单位特点规划!$A$2:$A$37,MATCH(B9,[1]单位特点规划!$B$2:$B$37,0))} -> 1007 | I9: =INDEX([1]单位特点规划!D$2:D$36,MATCH($H9,[1]单位特点规划!$A$2:$A$36,0))/10000 -> 1.53 | J9: =INDEX([1]单位特点规划!E$2:E$36,MATCH($H9,[1]单位特点规划!$A$2:$A$36,0))/10000 -> 0 | K9: =INDEX([1]单位特点规划!F$2:F$36,MATCH($H9,[1]单位特点规划!$A$2:$A$36,0))/10000 -> 1.35 | L9: =INDEX([1]单位特点规划!G$2:G$36,MATCH($H9,[1]单位特点规划!$A$2:$A$36,0))/10000 -> 1.87
A10: 10108 | B10: 幻影坦克 | C10: =I10 -> 1.66 | D10: =J10 -> 0 | E10: =K10 -> 1.57 | F10: =L10 -> 1.85 | G10: FALSE | H10: {=INDEX([1]单位特点规划!$A$2:$A$37,MATCH(B10,[1]单位特点规划!$B$2:$B$37,0))} -> 1001 | I10: =INDEX([1]单位特点规划!D$2:D$36,MATCH($H10,[1]单位特点规划!$A$2:$A$36,0))/10000 -> 1.66 | J10: =INDEX([1]单位特点规划!E$2:E$36,MATCH($H10,[1]单位特点规划!$A$2:$A$36,0))/10000 -> 0 | K10: =INDEX([1]单位特点规划!F$2:F$36,MATCH($H10,[1]单位特点规划!$A$2:$A$36,0))/10000 -> 1.57 | L10: =INDEX([1]单位特点规划!G$2:G$36,MATCH($H10,[1]单位特点规划!$A$2:$A$36,0))/10000 -> 1.85
A11: 10109 | B11: 天启坦克 | C11: =I11 -> 1.51 | D11: =J11 -> 0.75 | E11: =K11 -> 2.83 | F11: =L11 -> 1.29 | G11: FALSE | H11: {=INDEX([1]单位特点规划!$A$2:$A$37,MATCH(B11,[1]单位特点规划!$B$2:$B$37,0))} -> 1002 | I11: =INDEX([1]单位特点规划!D$2:D$36,MATCH($H11,[1]单位特点规划!$A$2:$A$36,0))/10000 -> 1.51 | J11: =INDEX([1]单位特点规划!E$2:E$36,MATCH($H11,[1]单位特点规划!$A$2:$A$36,0))/10000 -> 0.75 | K11: =INDEX([1]单位特点规划!F$2:F$36,MATCH($H11,[1]单位特点规划!$A$2:$A$36,0))/10000 -> 2.83 | L11: =INDEX([1]单位特点规划!G$2:G$36,MATCH($H11,[1]单位特点规划!$A$2:$A$36,0))/10000 -> 1.29
A12: 10110 | B12: 未来坦克 | C12: =I12 -> 4.87 | D12: =J12 -> 0 | E12: =K12 -> 2.7 | F12: =L12 -> 2.01 | G12: FALSE | H12: {=INDEX([1]单位特点规划!$A$2:$A$37,MATCH(B12,[1]单位特点规划!$B$2:$B$37,0))} -> 1010 | I12: =INDEX([1]单位特点规划!D$2:D$36,MATCH($H12,[1]单位特点规划!$A$2:$A$36,0))/10000 -> 4.87 | J12: =INDEX([1]单位特点规划!E$2:E$36,MATCH($H12,[1]单位特点规划!$A$2:$A$36,0))/10000 -> 0 | K12: =INDEX([1]单位特点规划!F$2:F$36,MATCH($H12,[1]单位特点规划!$A$2:$A$36,0))/10000 -> 2.7 | L12: =INDEX([1]单位特点规划!G$2:G$36,MATCH($H12,[1]单位特点规划!$A$2:$A$36,0))/10000 -> 2.01
A13: 10111 | B13: 鬼王机甲 | C13: =I13 -> 1.73 | D13: =J13 -> 1.903 | E13: =K13 -> 3.62 | F13: =L13 -> 3.03 | G13: FALSE | H13: {=INDEX([1]单位特点规划!$A$2:$A$37,MATCH(B13,[1]单位特点规划!$B$2:$B$37,0))} -> 1011 | I13: =INDEX([1]单位特点规划!D$2:D$36,MATCH($H13,[1]单位特点规划!$A$2:$A$36,0))/10000 -> 1.73 | J13: =INDEX([1]单位特点规划!E$2:E$36,MATCH($H13,[1]单位特点规划!$A$2:$A$36,0))/10000 -> 1.903 | K13: =INDEX([1]单位特点规划!F$2:F$36,MATCH($H13,[1]单位特点规划!$A$2:$A$36,0))/10000 -> 3.62 | L13: =INDEX([1]单位特点规划!G$2:G$36,MATCH($H13,[1]单位特点规划!$A$2:$A$36,0))/10000 -> 3.03
A14: 10112 | B14: 神经突击车 | C14: =I14 -> 0.51 | D14: =J14 -> 0 | E14: =K14 -> 1.07 | F14: =L14 -> 0.19 | G14: FALSE | H14: {=INDEX([1]单位特点规划!$A$2:$A$37,MATCH(B14,[1]单位特点规划!$B$2:$B$37,0))} -> 2007 | I14: =INDEX([1]单位特点规划!D$2:D$36,MATCH($H14,[1]单位特点规划!$A$2:$A$36,0))/10000 -> 0.51 | J14: =INDEX([1]单位特点规划!E$2:E$36,MATCH($H14,[1]单位特点规划!$A$2:$A$36,0))/10000 -> 0 | K14: =INDEX([1]单位特点规划!F$2:F$36,MATCH($H14,[1]单位特点规划!$A$2:$A$36,0))/10000 -> 1.07 | L14: =INDEX([1]单位特点规划!G$2:G$36,MATCH($H14,[1]单位特点规划!$A$2:$A$36,0))/10000 -> 0.19
... A34: 10132 | B34: 娜塔莎 | C34: =I34 -> 0.5 | D34: =J34 -> 12 | E34: =K34 -> 0.87 | F34: =L34 -> 1.03 | G34: FALSE | H34: {=INDEX([1]单位特点规划!$A$2:$A$37,MATCH(B34,[1]单位特点规划!$B$2:$B$37,0))} -> 4003 | I34: =INDEX([1]单位特点规划!D$2:D$36,MATCH($H34,[1]单位特点规划!$A$2:$A$36,0))/10000 -> 0.5 | J34: =INDEX([1]单位特点规划!E$2:E$36,MATCH($H34,[1]单位特点规划!$A$2:$A$36,0))/10000 -> 12 | K34: =INDEX([1]单位特点规划!F$2:F$36,MATCH($H34,[1]单位特点规划!$A$2:$A$36,0))/10000 -> 0.87 | L34: =INDEX([1]单位特点规划!G$2:G$36,MATCH($H34,[1]单位特点规划!$A$2:$A$36,0))/10000 -> 1.03
A35: 10133 | B35: 狗_特殊 | C35: 1 | D35: 0 | E35: 0.8 | F35: =0 -> 0 | G35: FALSE
A36: 10134 | B36: 恐怖机器人_特殊 | C36: 1.66 | D36: 0 | E36: 0.87 | F36: 0.85 | G36: FALSE
A37: 10135 | B37: 工程师_特殊_不会动 | C37: 0.13 | D37: 0 | E37: 1.09 | F37: 1.18 | G37: FALSE
A38: 10136 | B38: 美国大兵_特殊_不会射导弹 | C38: 0.22 | D38: 0.45 | E38: 0.45 | F38: 0.32 | G38: FALSE
A39: 10137 | B39: 采圆盘加强的超时空 | C39: =ROUND(0.86*1.33,2) -> 1.14 | D39: 0 | E39: =ROUND(1.16*1.33,2) -> 1.54 | F39: =ROUND(0.71*1.33,2) -> 0.94 | G39: FALSE
A40: 20000 | B40: 世界boss | C40: 0 | D40: 0 | E40: 10 | F40: =0 -> 0 | G40: FALSE
A41: 20001 | B41: 总部 | C41: 1 | D41: 0 | E41: 6 | F41: 0 | G41: FALSE
A42: 20002 | B42: 总部 | C42: 0 | D42: 0 | E42: 6 | F42: 0 | G42: FALSE
A43: 20003 | B43: 铁丝网 | C43: 0 | D43: 0 | E43: 0.05 | F43: 0 | G43: FALSE
A44: 20004 | B44: 弹药箱 | C44: 0 | D44: 0 | E44: 0.07 | F44: 0 | G44: FALSE
A45: 20005 | B45: 沙包竖 | C45: 0 | D45: 0 | E45: 0.1 | F45: 0 | G45: FALSE
A46: 20006 | B46: 沙包横 | C46: 0 | D46: 0 | E46: 0.1 | F46: 0 | G46: FALSE
A47: 20007 | B47: 沙包竖弯 | C47: 0 | D47: 0 | E47: 0.1 | F47: 0 | G47: FALSE
A48: 20008 | B48: 地堡 | C48: 0.15 | D48: 0 | E48: 0.15 | F48: 0 | G48: FALSE
A49: 20009 | B49: 地对空飞弹 | C49: 0.08 | D49: 0 | E49: 0.08 | F49: 0 | G49: FALSE
A50: 20010 | B50: 列车_1 | C50: 0 | D50: 0 | E50: 0.05 | F50: 0 | G50: FALSE
A51: 20011 | B51: 列车_2 | C51: 0 | D51: 0 | E51: 0.05 | F51: 0 | G51: FALSE
A52: 20012 | B52: 列车_3 | C52: 0 | D52: 0 | E52: 0.05 | F52: 0 | G52: FALSE
... A85: 20045 | B85: 秘密武器 | C85: 0 | D85: 0 | E85: 3 | F85: 0 | G85: FALSE
A86: 20100 | B86: 战斗碉堡 | C86: 0.3 | D86: 0 | E86: 1 | F86: 0
A87: 20101 | B87: 磁暴线圈 | C87: 0.3 | D87: 0 | E87: 0.3 | F87: 0
A88: 20102 | B88: 心灵控制塔 | C88: 0.3 | D88: 0 | E88: 0.3 | F88: 0
A89: 20103 | B89: EMP冲击塔 | C89: 0.3 | D89: 0 | E89: 0.3 | F89: 0
A90: 20104 | B90: 光棱塔 | C90: 0.3 | D90: 0 | E90: 0.3 | F90: 0
A91: 20105 | B91: 盖特机炮 | C91: 0.3 | D91: 0 | E91: 0.3 | F91: 0
...

Sheet 等级属性
A1: 级别 | B1: 攻击 | C1: 副攻击 | D1: 防御 | E1: 生命 | F1: 彭涨系数 | G1: 2.4 | H1: =F101 -> 6.2780316 | K1: 辅助
A2: 1 | B2: 100 | C2: 100 | D2: 68 | E2: 330 | F2: 1 | K2: 1.1
A3: 2 | B3: 106 | C3: 106 | D3: 72 | E3: 350 | F3: =1+ROUND(A3/50,2)^G$1 -> 1.0004415 | K3: 1.1
A4: 3 | B4: 109 | C4: 109 | D4: 75 | E4: 360 | F4: =1+ROUND(A4/50,2)^G$1 -> 1.0011683 | K4: 1.1
A5: 4 | B5: 112 | C5: 112 | D5: 77 | E5: 370 | F5: =1+ROUND(A5/50,2)^G$1 -> 1.0023303 | K5: 1.1
A6: 5 | B6: 115 | C6: 115 | D6: 79 | E6: 380 | F6: =1+ROUND(A6/50,2)^G$1 -> 1.0039811 | K6: 1.1
A7: 6 | B7: 118 | C7: 118 | D7: 81 | E7: 389 | F7: =1+ROUND(A7/50,2)^G$1 -> 1.0061664 | K7: 1.1
A8: 7 | B8: 121 | C8: 121 | D8: 83 | E8: 399 | F8: =1+ROUND(A8/50,2)^G$1 -> 1.008927 | K8: 1.1
A9: 8 | B9: 124 | C9: 124 | D9: 85 | E9: 410 | F9: =1+ROUND(A9/50,2)^G$1 -> 1.0122995 | K9: 1.1
A10: 9 | B10: 127 | C10: 127 | D10: 87 | E10: 421 | F10: =1+ROUND(A10/50,2)^G$1 -> 1.0163175 | K10: 1.1
A11: 10 | B11: 131 | C11: 131 | D11: 89 | E11: 432 | F11: =1+ROUND(A11/50,2)^G$1 -> 1.0210122 | K11: 1.1
A12: 11 | B12: 134 | C12: 134 | D12: 91 | E12: 443 | F12: =1+ROUND(A12/50,2)^G$1 -> 1.0264128 | K12: 1.1
A13: 12 | B13: 138 | C13: 138 | D13: 94 | E13: 458 | F13: =1+ROUND(A13/50,2)^G$1 -> 1.0325467 | J13: =(1+0.5)*2+1.8+1.5 -> 6.3 | K13: 1.1
A14: 13 | B14: 143 | C14: 143 | D14: 98 | E14: 473 | F14: =1+ROUND(A14/50,2)^G$1 -> 1.0394399 | K14: 1.1
A15: 14 | B15: 148 | C15: 148 | D15: 102 | E15: 488 | F15: =1+ROUND(A15/50,2)^G$1 -> 1.0471172 | K15: 1.1
A16: 15 | B16: 153 | C16: 153 | D16: 104 | E16: 505 | F16: =1+ROUND(A16/50,2)^G$1 -> 1.0556021 | K16: 1.1
A17: 16 | B17: 158 | C17: 158 | D17: 109 | E17: 521 | F17: =1+ROUND(A17/50,2)^G$1 -> 1.0649172 | K17: 1.1
A18: 17 | B18: 163 | C18: 163 | D18: 112 | E18: 538 | F18: =1+ROUND(A18/50,2)^G$1 -> 1.0750843 | K18: 1.1
A19: 18 | B19: 168 | C19: 168 | D19: 115 | E19: 556 | F19: =1+ROUND(A19/50,2)^G$1 -> 1.0861244 | K19: 1.1
A20: 19 | B20: 174 | C20: 174 | D20: 120 | E20: 574 | F20: =1+ROUND(A20/50,2)^G$1 -> 1.0980575 | K20: 1.1
A21: 20 | B21: 179 | C21: 179 | D21: 123 | E21: 593 | F21: =1+ROUND(A21/50,2)^G$1 -> 1.1109032 | K21: 1.1
A22: 21 | B22: 186 | C22: 186 | D22: 128 | E22: 616 | F22: =1+ROUND(A22/50,2)^G$1 -> 1.1246804 | K22: 1.1
A23: 22 | B23: 194 | C23: 194 | D23: 132 | E23: 640 | F23: =1+ROUND(A23/50,2)^G$1 -> 1.1394076 | K23: 1.1
A24: 23 | B24: 201 | C24: 201 | D24: 139 | E24: 666 | F24: =1+ROUND(A24/50,2)^G$1 -> 1.1551025 | K24: 1.1
A25: 24 | B25: 209 | C25: 209 | D25: 145 | E25: 692 | F25: =1+ROUND(A25/50,2)^G$1 -> 1.1717825 | K25: 1.1
... A147: 146 | B147: 119023 | C147: 119023 | D147: 82637 | E147: 969337 | F147: =1+ROUND(A147/50,2)^G$1 -> 14.089373 | K147: 2.7147055
A148: 147 | B148: 124480 | C148: 124480 | D148: 86420 | E148: 373441 | F148: =1+ROUND(A148/50,2)^G$1 -> 14.305573
A149: 148 | B149: 130092 | C149: 130092 | D149: 90337 | E149: 390278 | F149: =1+ROUND(A149/50,2)^G$1 -> 14.523843
A150: 149 | B150: 135862 | C150: 135862 | D150: 94337 | E150: 407587 | F150: =1+ROUND(A150/50,2)^G$1 -> 14.744186
A151: 150 | B151: 141792 | C151: 141792 | D151: 98448 | E151: 425376 | F151: =1+ROUND(A151/50,2)^G$1 -> 14.96661
A152: 151 | B152: 148854 | C152: 148854 | D152: 103327 | E152: 446564 | F152: =1+ROUND(A152/50,2)^G$1 -> 15.19112
A153: 152 | B153: 156149 | C153: 156149 | D153: 108435 | E153: 468449 | F153: =1+ROUND(A153/50,2)^G$1 -> 15.41772
A154: 153 | B154: 163652 | C154: 163652 | D154: 113599 | E154: 490958 | F154: =1+ROUND(A154/50,2)^G$1 -> 15.646418
A155: 154 | B155: 171366 | C155: 171366 | D155: 118968 | E155: 514100 | F155: =1+ROUND(A155/50,2)^G$1 -> 15.877218
A156: 155 | B156: 179295 | C156: 179295 | D156: 124488 | E156: 537887 | F156: =1+ROUND(A156/50,2)^G$1 -> 16.110125
A157: 156 | B157: 187443 | C157: 187443 | D157: 130096 | E157: 562331 | F157: =1+ROUND(A157/50,2)^G$1 -> 16.345146
A158: 157 | B158: 195813 | C158: 195813 | D158: 135954 | E158: 587441 | F158: =1+ROUND(A158/50,2)^G$1 -> 16.582285
A159: 158 | B159: 204409 | C159: 204409 | D159: 141937 | E159: 613229 | F159: =1+ROUND(A159/50,2)^G$1 -> 16.821549
... A201: 200 | B201: 1221935 | C201: 1221935 | D201: 848510 | E201: 3665805 | F201: =1+ROUND(A201/50,2)^G$1 -> 28.857618

Sheet 统率力
A1: 章 | B1: 统率力
A2: 1 | B2: 15
A3: 2 | B3: =B2+5 -> 20
A4: 3 | B4: =B3+5 -> 25
A5: 4 | B5: =B4+5 -> 30
A6: 5 | B6: =B5+5 -> 35
A7: 6 | B7: =B6+5 -> 40
A8: 7 | B8: =B7+5 -> 45
A9: 8 | B9: =B8+5 -> 50
A10: 9 | B10: =B9+5 -> 55
A11: 10 | B11: =B10 -> 55
A12: 11 | B12: =B11 -> 55
A13: 12 | B13: =B12 -> 55

Sheet Sheet1
A1: 怪物id 1：战役副本（类型1+章2+节2+怪2） 3：日常副本（类型1+章2+节2+怪2） 4：组队副本（类型1+星2+节2+怪2）【礼包单位的测试：41+三位编码+怪物2】 5：夺宝奇兵 6：世界BOSS 7：测试 8：地图摆件（地图8+章2+节2+怪1） 9：抵抗侵略 | B1: 名字 | C1: shareDataID | D1: 所占的人口 代码会把属性名变成： populace | E1: 主武器攻击 代码会把属性名变成： main_atk | F1: 副武器攻击 代码会把属性名变成： minor_atk | G1: 防御 代码会把属性名变成： def | H1: 生命 代码会把属性名变成： hp | I1: 等级 代码会把属性名变成： level
A2: id | C2: s | D2: p | E2: a | F2: b | G2: d | H2: h
A3: int | B3: string | C3: int | D3: int | E3: int | F3: int | G3: int | H3: int
A4: 1020905 | B4: 天启坦克 | C4: 10109 | D4: 5 | E4: 93 | F4: 46 | G4: 109 | H4: 526 | I4: 8
A5: 5101001 | B5: 美国大兵 | C5: 10101 | D5: 1 | E5: 43 | F5: 88 | G5: 36 | H5: 117 | I5: 3
A6: 5101002 | B6: 灰熊坦克 | C6: 10103 | D6: 2 | E6: 109 | F6: 0 | G6: 56 | H6: 272 | I6: 3
A7: 5101003 | B7: 犀牛坦克 | C7: 10104 | D7: 2 | E7: 117 | F7: 0 | G7: 75 | H7: 261 | I7: 3
A8: 5101004 | B8: 盖特坦克 | C8: 10102 | D8: 2 | E8: 51 | F8: 0 | G8: 46 | H8: 120 | I8: 3
A9: 5101005 | B9: 多功能车 | C9: 10120 | D9: 3 | E9: 121 | F9: 0 | G9: 39 | H9: 277 | I9: 3
A10: 5102001 | B10: 美国大兵 | C10: 10101 | D10: 1 | E10: 34 | F10: 70 | G10: 28 | H10: 140 | I10: 10
A11: 5102002 | B11: 灰熊坦克 | C11: 10103 | D11: 2 | E11: 131 | F11: 0 | G11: 66 | H11: 324 | I11: 10
A12: 5102003 | B12: 犀牛坦克 | C12: 10104 | D12: 2 | E12: 140 | F12: 0 | G12: 89 | H12: 312 | I12: 10
A13: 5102004 | B13: 冷冻直升机 | C13: 10125 | D13: 2 | E13: 109 | F13: 0 | G13: 36 | H13: 321 | I13: 10
A14: 5102005 | B14: 多功能车 | C14: 10120 | D14: 3 | E14: 145 | F14: 0 | G14: 47 | H14: 330 | I14: 10
A15: 5102006 | B15: 盖特坦克 | C15: 10102 | D15: 2 | E15: 60 | F15: 0 | G15: 55 | H15: 143 | I15: 10
... A26: 5104005 | B26: 恐怖机器人 | C26: 10134 | D26: 1 | E26: 499 | F26: 0 | G26: 146 | H26: 524 | I26: 35
